Workbook
Name 상미70: 정리표!#REF!
Name 상미70: '창고1(실사표)'!#REF!
Name 상미75: 정리표!$N$1
Name 상미75: '창고1(실사표)'!$N$1

Sheet 월마감
C1: 한국통운 재고현황
A3: 기존코드 | B3: SAP코드 | C3: Brand Name | D3: 구분 | E3: 940P | F3: 아주 | G3: 940P | H3: 아주 | I3: 잔량 | J3: 보류재고 | K3: 총합계 | L3: 전산 | M3: 주간상차 | N3: 차이 | P3: 940P | Q3: 아주 | R3: 잔량 | S3: 보류재고 | T3: 합계 | U3: 차이 | V3: SAP | W3: 최종차이
A4: 7870 | B4: MM7870 | C4: 미닛 오렌지 180NRB 3X12 | D4: 180NRB | F4: 72 | G4: 0 | H4: 0 | I4: 71 | J4: 0 | K4: 71 | L4: 73 | M4: 0 | N4: -2
A5: 7011 | B5: MM7011 | C5: 미닛 홈스타오렌+자몽 180NRB 3X12 | D5: 180NRB | F5: 72 | G5: 0 | H5: 936 | I5: 28 | J5: 0 | K5: 964 | L5: 964 | M5: 0 | N5: 0
A6: 7871 | B6: MM7871 | C6: 미닛 포도 180NRB 3X12 | D6: 180NRB | F6: 72 | G6: 0 | H6: 936 | I6: 48 | J6: 0 | K6: 984 | L6: 983 | M6: 0 | N6: 1
A7: 7873 | B7: MM7873 | C7: 미닛 알로에 180NRB 3X12 | D7: 180NRB | F7: 72 | G7: 0 | H7: 0 | I7: 0 | J7: 0 | K7: 0 | L7: 0 | M7: 0 | N7: 0
A8: 7875 | B8: MM7875 | C8: 미닛 오렌+포도+감귤 180NRB 3X12 | D8: 180NRB | F8: 64 | G8: 0 | H8: 0 | I8: 0 | J8: 0 | K8: 0 | L8: 0 | M8: 0 | N8: 0
A9: 7872 | B9: MM7872 | C9: 미닛 제주감귤 180NRB 3X12 | D9: 180NRB | F9: 64 | G9: 0 | H9: 0 | I9: 0 | J9: 0 | K9: 0 | L9: 0 | M9: 0 | N9: 0
A10: 7876 | B10: MM7876 | C10: 미닛 오렌+포도+알로 180NRB 3X12 | D10: 180NRB | F10: 72 | G10: 0 | H10: 648 | I10: 72 | J10: 0 | K10: 720 | L10: 716 | M10: 0 | N10: 4
A11: 7877 | B11: MM7877 | C11: 미닛 감귤+알로+토마 180NRB 3X12 | D11: 180NRB | F11: 72 | G11: 0 | H11: 432 | I11: 50 | J11: 0 | K11: 482 | L11: 480 | M11: 0 | N11: 2
A12: 7878 | B12: MM7878 | C12: 미닛 감귤+포도+매실 180NRB 3X12 | D12: 180NRB | F12: 72 | G12: 0 | H12: 720 | I12: 0 | J12: 0 | K12: 720 | L12: 720 | M12: 0 | N12: 0
A13: 7915 | B13: MM7915 | C13: 미닛 아사+백포도알로 180NRB 3X12 | D13: 180NRB | F13: 72 | G13: 0 | H13: 0 | I13: 0 | J13: 0 | K13: 0 | L13: 0 | M13: 0 | N13: 0
A14: 5630 | B14: ZC5630 | C14: 지코 플레인 330TTR X12 | D14: NRB | F14: 240 | G14: 0 | H14: 0 | I14: 24 | J14: 0 | K14: 24 | L14: 24 | M14: 0 | N14: 0
A15: 5631 | B15: ZC5631 | C15: 지코 플레인 330TTR 3X4 | D15: NRB | F15: 180 | G15: 0 | H15: 0 | I15: 2364 | J15: 0 | K15: 2364 | L15: 2363 | M15: 0 | N15: 1
... A17: 8211 | B17: HO8211 | C17: 홍차화원 벛꽃 350PET 4X6 | D17: PET | F17: 84 | G17: 0 | H17: 2772 | I17: 66 | J17: 167 | K17: 3005 | L17: 3005 | M17: 0 | N17: 0
A18: 6194 | B18: CC6194 | C18: 코카콜라 355RGB X24 | D18: RGB | E18: 36 | G18: 0 | H18: 0 | I18: 31 | J18: 0 | K18: 31 | L18: 31 | M18: 0 | N18: 0
A19: 5490 | B19: GL5490 | C19: 글라소 파워씨 500PET X12 | D19: 글라소 | E19: 91 | G19: 0 | H19: 0 | I19: 0 | J19: 0 | K19: 0 | L19: 0 | M19: 0 | N19: 0
A20: 5492 | B20: GL5492 | C20: 글라소 에너지 500PET X12 | D20: 글라소 | E20: 91 | G20: 0 | H20: 0 | I20: 0 | J20: 0 | K20: 0 | L20: 0 | M20: 0 | N20: 0
A21: 5535 | B21: GL5535 | C21: 글라소 코코워터 355PET 4X6 | D21: 글라소 | F21: 64 | G21: 0 | H21: 0 | I21: 0 | J21: 0 | K21: 0 | L21: 0 | M21: 0 | N21: 0
A22: 5560 | B22: GL5560 | C22: 글라소 파워씨 500PET 4X6 | D22: 글라소 | F22: 56 | G22: 0 | H22: 1568 | I22: 129 | J22: 0 | K22: 1697 | L22: 1697 | M22: 0 | N22: 0
A23: 5561 | B23: GL5561 | C23: 글라소 에너지 500PET 4X6 | D23: 글라소 | F23: 56 | G23: 0 | H23: 1120 | I23: 118 | J23: 0 | K23: 1238 | L23: 1238 | M23: 0 | N23: 0
A24: 5562 | B24: GL5562 | C24: 글라소 멀티브이 500PET 4X6 | D24: 글라소 | E24: 36 | F24: 56 | G24: 0 | H24: 672 | I24: 110 | J24: 0 | K24: 782 | L24: 785 | M24: 0 | N24: -3
A25: 5563 | B25: GL5563 | C25: 글라소 XXX 500PET 4X6 | D25: 글라소 | F25: 56 | G25: 0 | H25: 168 | I25: 18 | J25: 0 | K25: 186 | L25: 186 | M25: 0 | N25: 0
A26: 5564 | B26: GL5564 | C26: 글라소 에센셜 500PET 4X6 | D26: 글라소 | F26: 56 | G26: 0 | H26: 0 | I26: 0 | J26: 0 | K26: 0 | L26: 0 | M26: 0 | N26: 0
A27: 5454 | B27: GL5454 | C27: 글라소 백포도&레몬 450PET 4X6 | D27: 글라소 | F27: 60 | G27: 0 | H27: 0 | I27: 0 | J27: 0 | K27: 0 | L27: 0 | M27: 0 | N27: 0
A28: 5455 | B28: GL5455 | C28: 글라소 복숭아&자몽 450PET 4X6 | D28: 글라소 | F28: 60 | G28: 0 | H28: 0 | I28: 0 | J28: 0 | K28: 0 | L28: 0 | M28: 0 | N28: 0
A29: 5568 | B29: GL5568 | C29: 글라소 지크리에이터 500PET 4X6 | D29: 글라소 | F29: 56 | G29: 0 | H29: 0 | I29: 0 | J29: 0 | K29: 0 | L29: 0 | M29: 0 | N29: 0
A30: 8188 | B30: TY8188 | C30: S)태양의 마테차 500PET 4X6 | D30: 마테차 | E30: 40 | F30: 63 | G30: 0 | H30: 5481 | I30: 86 | J30: 0 | K30: 5567 | L30: 5317 | M30: 252 | N30: -2
A31: 8187 | B31: TY8187 | C31: 태양의 마테차 500PET X24 | D31: 마테차 | F31: 63 | G31: 0 | H31: 0 | I31: 0 | J31: 0 | K31: 0 | L31: 0 | M31: 0 | N31: 0
A32: 8811 | B32: VS8811 | C32: 휘오 철원순수 500PET X20 | D32: 물 | E32: 72 | F32: 96 | G32: 72 | H32: 0 | I32: 26 | J32: 0 | K32: 98 | L32: 103 | M32: 0 | N32: -5 | P32: 1 | R32: 26 | T32: =(P32*E32)+(Q32*F32)+R32+S32 -> 98 | U32: =K32-T32 -> 0 | V32: =SUMIF(SAP!#REF!,월마감!B:B,SAP!#REF!) -> #REF! | W32: =T32-V32 -> #REF!
A33: 8812 | B33: VS8812 | C33: 휘오 철원순수 2.0PET X6 | D33: 물 | E33: 60 | F33: 72 | G33: 180 | H33: 0 | I33: 27 | J33: 0 | K33: 207 | L33: 208 | M33: 0 | N33: -1
A34: 8813 | B34: VS8813 | C34: SSP)휘오 철원순수 500PET X20 | D34: 물 | E34: 72 | G34: 0 | H34: 0 | I34: 0 | J34: 0 | K34: 0 | L34: 0 | M34: 0 | N34: 0
A35: 8815 | B35: VJ8815 | C35: 휘오 제주V워터 500PET X20 | D35: 물 | F35: 112 | G35: 0 | H35: 112 | I35: 72 | J35: 0 | K35: 184 | L35: 185 | M35: 0 | N35: 0
A36: 8816 | B36: VJ8816 | C36: 휘오 제주V워터 2.0PET X6 | D36: 물 | F36: 100 | G36: 0 | H36: 100 | I36: 45 | J36: 0 | K36: 145 | L36: 141 | M36: 0 | N36: 4
A37: 8830 | B37: VJ8830 | C37: 휘오 제주V워터 E 2.0PET X6(5+1) | D37: 물 | F37: 100 | G37: 0 | H37: 0 | I37: 0 | J37: 0 | K37: 0 | L37: 0 | M37: 0 | N37: 0
A38: 8794 | B38: VD8794 | C38: 휘오 다이아몬드SE 400PET X20 | D38: 물 | F38: 91 | G38: 0 | H38: 0 | I38: 0 | J38: 0 | K38: 0 | L38: 0 | M38: 0 | N38: 0
A39: 4230 | B39: SG4230 | C39: 씨그램 미네랄워터 500PET X20 | D39: 물 | E39: 72 | F39: 96 | G39: 864 | H39: 0 | I39: 186 | J39: 0 | K39: 1050 | L39: 1051 | M39: 0 | N39: -1
A40: 8702 | B40: VD8702 | C40: S)휘오 다이아스파클링 350PET 4X6 | D40: 물 | F40: 50 | G40: 0 | H40: 400 | I40: 32 | J40: 59 | K40: 491 | L40: 495 | M40: 0 | N40: -4 | Q40: 8 | R40: 32 | S40: 59 | T40: =(P40*E40)+(Q40*F40)+R40+S40 -> 491 | U40: =K40-T40 -> 0 | V40: =SUMIF(SAP!#REF!,월마감!B:B,SAP!#REF!) -> #REF! | W40: =T40-V40 -> #REF!
A41: 7142 | B41: MM7142 | C41: 미닛 조이오렌지 240CAN X30 | D41: 비탄산캔 | E41: 108 | F41: 144 | G41: 0 | H41: 0 | I41: 0 | J41: 0 | K41: 0 | L41: 0 | M41: 0 | N41: 0 | P41: 1 | T41: =(P41*E41)+(Q41*F41)+R41+S41 -> 108 | U41: =K41-T41 -> -108 | V41: =SUMIF(SAP!#REF!,월마감!B:B,SAP!#REF!) -> #REF! | W41: =T41-V41 -> #REF!
A42: 4166 | B42: SW4166 | C42: S)슈웹스 레몬토닉 350PET 4X6 | D42: 슈웹스 | E42: 40 | F42: 50 | G42: 0 | H42: 2150 | I42: 60 | J42: 7 | K42: 2217 | L42: 1958 | M42: 250 | N42: 9 | Q42: 39 | R42: =20+18+7+20 -> 65 | T42: =(P42*E42)+(Q42*F42)+R42+S42 -> 2015 | U42: =K42-T42 -> 202 | V42: =SUMIF(SAP!#REF!,월마감!B:B,SAP!#REF!) -> #REF! | W42: =T42-V42 -> #REF!
...

Sheet 제품등록
A1: 구코드 | B1: 신코드 | C1: 제품명 | D1: 내부소비기한(일) (QA기준) | E1: 내부소비기한 (SCM기준) | F1: 법적유효기간(일) | G1: 유효잔여일
A2: 4218 | B2: AB4218 | C2: 암바사 345CAN X24 | D2: 183 | E2: 182.5 | F2: 365 | G2: 182
A3: 4219 | B3: AB4219 | C3: 암바사 345CAN 4X6 | D3: 183 | E3: 182.5 | F3: 365 | G3: 182
A4: 4224 | B4: AB4224 | C4: 암바사 500PET X24 | D4: 84 | E4: 182.5 | F4: 365 | G4: 281
A5: 4225 | B5: AB4225 | C5: 암바사 350PET X24 | D5: 84 | E5: 182.5 | F5: 365 | G5: 281
A6: 4226 | B6: AB4226 | C6: 암바사350(4X6) | D6: 84 | E6: 182.5 | F6: 365 | G6: 281
A7: 4549 | B7: AB4549 | C7: 암바사화이트1.5PET X12 | D7: 98 | E7: 182.5 | F7: 365 | G7: 267
A8: 4833 | B8: AB4833 | C8: 암바사화이트250CAN 5X6 | D8: 183 | E8: 182.5 | F8: 365 | G8: 182
A9: 4834 | B9: AB4834 | C9: 암바사화이트250CAN X30 | D9: 183 | E9: 182.5 | F9: 365 | G9: 182
A10: 4845 | B10: AB4845 | C10: 암바사 SSP 250CAN X30 | D10: 183 | E10: 182.5 | F10: 365 | G10: 182
A11: 4859 | B11: AB4859 | C11: 암바사 SSP 355CAN X24 | D11: 183 | E11: 182.5 | F11: 365 | G11: 182
A12: 5752 | B12: AB5752 | C12: 암바사 300PET X24 | D12: 70 | E12: 182.5 | F12: 365 | G12: 295
A13: 4340 | B13: AD4340 | C13: 아데스 아몬드 오리지널 210PET X24 | D13: 152 | E13: 152 | F13: 304 | G13: 152
... A40: 1210 | B40: CA1210 | C40: 캐 클럽소다250CAN X30 | D40: 365 | E40: 365 | F40: 730 | G40: 365
A41: CC0001 | B41: CC0001 | C41: 온)코카콜라 390PET X20 | D41: 70 | E41: 182.5 | F41: 365 | G41: 295
A42: 62 | B42: CC0062 | C42: 코카-콜라 1.25PET X12 | D42: 98 | E42: 182.5 | F42: 365 | G42: 267
A43: 360 | B43: CC0360 | C43: 코카-콜라 20LBIB PMX | D43: 75 | E43: 91.5 | F43: 183 | G43: 108
A44: 446 | B44: CC0446 | C44: 코카콜라 350CAN X24 | D44: 365 | E44: 365 | F44: 730 | G44: 365
A45: 447 | B45: CC0447 | C45: 코카-콜라 355CAN X24 | D45: 365 | E45: 365 | F45: 730 | G45: 365
A46: 448 | B46: CC0448 | C46: 코카콜라-치킨355C X24 | D46: 365 | E46: 365 | F46: 730 | G46: 365
A47: 0449 | B47: CC0449 | C47: 코카콜라 330CAN X24 | D47: 365 | E47: 365 | F47: 730 | G47: 365
A48: 0451 | B48: CC0451 | C48: 코카콜라 330CAN 4X6 | D48: 365 | E48: 365 | F48: 730 | G48: 365
A49: 453 | B49: CC0453 | C49: 코카콜라 330CAN 4X6(4+2) | D49: 365 | E49: 365 | F49: 730 | G49: 365
A50: 1300 | B50: CC1300 | C50: 코카콜라SW 250CAN 5X6 | D50: 365 | E50: 365 | F50: 730 | G50: 365
A51: 1305 | B51: CC1305 | C51: 코카-콜라 315CAN 4X6 | D51: 365 | E51: 365 | F51: 730 | G51: 365
A52: 63 | B52: CC1333 | C52: M&P)코카-콜라1.25P X12 | D52: 98 | E52: 182.5 | F52: 365 | G52: 267
A53: 1333 | B53: CC1333 | C53: 코카콜라HP 1.25PETX12 | D53: 98 | E53: 182.5 | F53: 365 | G53: 267
A54: 1511 | B54: CC1511 | C54: 커피 코카콜라 250CAN X30 | D54: 365 | E54: 365 | F54: 730 | G54: 365
A55: 1512 | B55: CC1512 | C55: 커피 코카콜라 250CAN 5X6 | D55: 365 | E55: 365 | F55: 730 | G55: 365
A56: 1518 | B56: CC1518 | C56: 체리 코크 355CAN X24 | D56: 365 | E56: 365 | F56: 730 | G56: 365
A57: 1521 | B57: CC1521 | C57: 체리 코크(S) 355C 4X6 | D57: 365 | E57: 365 | F57: 730 | G57: 365
A58: 2430 | B58: CC2430 | C58: 코카콜라 185CAN X30 | D58: 365 | E58: 365 | F58: 730 | G58: 365
A59: 2440 | B59: CC2440 | C59: 코카-콜라 185CAN 5X6 | D59: 365 | E59: 365 | F59: 730 | G59: 365
A60: 2444 | B60: CC2444 | C60: 코카-콜라185C 5X6(4+2) | D60: 365 | E60: 365 | F60: 730 | G60: 365
... A118: 4623 | B118: CC4623 | C118: 보100)코카콜라 190RGB X24 | D118: 365 | E118: 365 | F118: 730 | G118: 365
A119: CC4634 | B119: CC4634 | C119: 코카콜라(B) 265NRB X24 | D119: 365 | E119: 365 | F119: 730 | G119: 365
A120: CC4635 | B120: CC4635 | C120: 코카콜라(A) 265NRB X24 | D120: 365 | E120: 365 | F120: 730 | G120: 365
A121: 4636 | B121: CC4636 | C121: 코카콜라 폴라베어 250NRB X24 | D121: 365 | E121: 365 | F121: 730 | G121: 365
A122: 4643 | B122: CC4643 | C122: 코카콜라 산타250NRB X24 | D122: 365 | E122: 365 | F122: 730 | G122: 365
A123: 4660 | B123: CC4660 | C123: 코크폴라베어250CAN 5X6 | D123: 365 | E123: 365 | F123: 730 | G123: 365
...

Sheet 재고차이
C1: 대신물류B동 재고현황
A3: 기존코드 | B3: SAP코드 | C3: Brand Name | D3: 940P | E3: 아주 | F3: 940P | G3: 아주 | H3: 잔량 | I3: 보류재고 | J3: 총합계 | K3: 전산 | L3: 주간상차 | M3: 차이 | N3: + | O3: - | P3: 차이내역 | Q3: 거래처파손교환/불량정리
A4: 4219 | B4: =VLOOKUP(A:A,제품등록!A:B,2,0) -> AB4219 | C4: =VLOOKUP(B4,제품등록!B:C,2,0) -> 암바사 345CAN 4X6 | E4: 100 | F4: =SUMIF('창고1(실사표)'!B:B,재고차이!A:A,'창고1(실사표)'!F:F)*D4+SUMIF('창고2(실사표)'!B:B,재고차이!A:A,'창고2(실사표)'!F:F)*D4+SUMIF('믹스(잔량실사표)'!B:B,재고차이!A:A,'믹스(잔량실사표)'!F:F)*D4 -> 0 | G4: =SUMIF('창고1(실사표)'!B:B,재고차이!A:A,'창고1(실사표)'!E:E)*E4+SUMIF('창고2(실사표)'!B:B,재고차이!A:A,'창고2(실사표)'!E:E)*E4+SUMIF('믹스(잔량실사표)'!B:B,재고차이!A:A,'믹스(잔량실사표)'!E:E)*E4 -> 0 | H4: =SUMIF('창고1(실사표)'!B:B,재고차이!A:A,'창고1(실사표)'!G:G)+SUMIF('창고2(실사표)'!B:B,재고차이!A:A,'창고2(실사표)'!G:G)++SUMIF('믹스(잔량실사표)'!B:B,재고차이!A:A,'믹스(잔량실사표)'!G:G) -> 0 | I4: =SUMIF('창고1(실사표)'!B:B,재고차이!A:A,'창고1(실사표)'!H:H)+SUMIF('창고2(실사표)'!B:B,재고차이!A:A,'창고2(실사표)'!H:H)++SUMIF('믹스(잔량실사표)'!B:B,재고차이!A:A,'믹스(잔량실사표)'!H:H) -> 0 | J4: =SUM(F4:I4) -> 0 | K4: =SUMIF(SAP!#REF!,재고차이!B:B,SAP!#REF!) -> #REF! | L4: =SUMIF(주간상차!A:A,재고차이!A:A,주간상차!E:E) -> 0 | M4: =J4-K4-L4-N4+O4+Q4 -> #REF! | Q4: =SUMIF(파손품!D:D,재고차이!B:B,파손품!I:I)+SUMIF(동파파손!D:D,재고차이!B:B,동파파손!I:I) -> 0 | R4: =M4/E4 -> #REF!
A5: 3214 | B5: =VLOOKUP(A:A,제품등록!A:B,2,0) -> FT3214 | C5: =VLOOKUP(B5,제품등록!B:C,2,0) -> 암바사 by 환타 345CAN 4X6 | E5: 100 | F5: =SUMIF('창고1(실사표)'!B:B,재고차이!A:A,'창고1(실사표)'!F:F)*D5+SUMIF('창고2(실사표)'!B:B,재고차이!A:A,'창고2(실사표)'!F:F)*D5+SUMIF('믹스(잔량실사표)'!B:B,재고차이!A:A,'믹스(잔량실사표)'!F:F)*D5 -> 0 | G5: =SUMIF('창고1(실사표)'!B:B,재고차이!A:A,'창고1(실사표)'!E:E)*E5+SUMIF('창고2(실사표)'!B:B,재고차이!A:A,'창고2(실사표)'!E:E)*E5+SUMIF('믹스(잔량실사표)'!B:B,재고차이!A:A,'믹스(잔량실사표)'!E:E)*E5 -> 0 | H5: =SUMIF('창고1(실사표)'!B:B,재고차이!A:A,'창고1(실사표)'!G:G)+SUMIF('창고2(실사표)'!B:B,재고차이!A:A,'창고2(실사표)'!G:G)++SUMIF('믹스(잔량실사표)'!B:B,재고차이!A:A,'믹스(잔량실사표)'!G:G) -> 0 | I5: =SUMIF('창고1(실사표)'!B:B,재고차이!A:A,'창고1(실사표)'!H:H)+SUMIF('창고2(실사표)'!B:B,재고차이!A:A,'창고2(실사표)'!H:H)++SUMIF('믹스(잔량실사표)'!B:B,재고차이!A:A,'믹스(잔량실사표)'!H:H) -> 0 | J5: =SUM(F5:I5) -> 0 | K5: =SUMIF(SAP!#REF!,재고차이!B:B,SAP!#REF!) -> #REF! | L5: =SUMIF(주간상차!A:A,재고차이!A:A,주간상차!E:E) -> 0 | M5: =J5-K5-L5-N5+O5+Q5 -> #REF! | Q5: =SUMIF(파손품!D:D,재고차이!B:B,파손품!I:I)+SUMIF(동파파손!D:D,재고차이!B:B,동파파손!I:I) -> 0 | R5: =M5/E5 -> #REF!
A6: 4833 | B6: =VLOOKUP(A:A,제품등록!A:B,2,0) -> AB4833 | C6: =VLOOKUP(B6,제품등록!B:C,2,0) -> 암바사화이트250CAN 5X6 | D6: 99 | E6: 132 | F6: =SUMIF('창고1(실사표)'!B:B,재고차이!A:A,'창고1(실사표)'!F:F)*D6+SUMIF('창고2(실사표)'!B:B,재고차이!A:A,'창고2(실사표)'!F:F)*D6+SUMIF('믹스(잔량실사표)'!B:B,재고차이!A:A,'믹스(잔량실사표)'!F:F)*D6 -> 0 | G6: =SUMIF('창고1(실사표)'!B:B,재고차이!A:A,'창고1(실사표)'!E:E)*E6+SUMIF('창고2(실사표)'!B:B,재고차이!A:A,'창고2(실사표)'!E:E)*E6+SUMIF('믹스(잔량실사표)'!B:B,재고차이!A:A,'믹스(잔량실사표)'!E:E)*E6 -> 0 | H6: =SUMIF('창고1(실사표)'!B:B,재고차이!A:A,'창고1(실사표)'!G:G)+SUMIF('창고2(실사표)'!B:B,재고차이!A:A,'창고2(실사표)'!G:G)++SUMIF('믹스(잔량실사표)'!B:B,재고차이!A:A,'믹스(잔량실사표)'!G:G) -> 0 | I6: =SUMIF('창고1(실사표)'!B:B,재고차이!A:A,'창고1(실사표)'!H:H)+SUMIF('창고2(실사표)'!B:B,재고차이!A:A,'창고2(실사표)'!H:H)++SUMIF('믹스(잔량실사표)'!B:B,재고차이!A:A,'믹스(잔량실사표)'!H:H) -> 0 | J6: =SUM(F6:I6) -> 0 | K6: =SUMIF(SAP!#REF!,재고차이!B:B,SAP!#REF!) -> #REF! | L6: =SUMIF(주간상차!A:A,재고차이!A:A,주간상차!E:E) -> 0 | M6: =J6-K6-L6-N6+O6+Q6 -> #REF! | Q6: =SUMIF(파손품!D:D,재고차이!B:B,파손품!I:I)+SUMIF(동파파손!D:D,재고차이!B:B,동파파손!I:I) -> 0 | R6: =M6/E6 -> #REF!
A7: 1193 | B7: =VLOOKUP(A:A,제품등록!A:B,2,0) -> CA1193 | C7: =VLOOKUP(B7,제품등록!B:C,2,0) -> 캐 진저엘 250CAN 5X6 | E7: 132 | F7: =SUMIF('창고1(실사표)'!B:B,재고차이!A:A,'창고1(실사표)'!F:F)*D7+SUMIF('창고2(실사표)'!B:B,재고차이!A:A,'창고2(실사표)'!F:F)*D7+SUMIF('믹스(잔량실사표)'!B:B,재고차이!A:A,'믹스(잔량실사표)'!F:F)*D7 -> 0 | G7: =SUMIF('창고1(실사표)'!B:B,재고차이!A:A,'창고1(실사표)'!E:E)*E7+SUMIF('창고2(실사표)'!B:B,재고차이!A:A,'창고2(실사표)'!E:E)*E7+SUMIF('믹스(잔량실사표)'!B:B,재고차이!A:A,'믹스(잔량실사표)'!E:E)*E7 -> 0 | H7: =SUMIF('창고1(실사표)'!B:B,재고차이!A:A,'창고1(실사표)'!G:G)+SUMIF('창고2(실사표)'!B:B,재고차이!A:A,'창고2(실사표)'!G:G)++SUMIF('믹스(잔량실사표)'!B:B,재고차이!A:A,'믹스(잔량실사표)'!G:G) -> 0 | I7: =SUMIF('창고1(실사표)'!B:B,재고차이!A:A,'창고1(실사표)'!H:H)+SUMIF('창고2(실사표)'!B:B,재고차이!A:A,'창고2(실사표)'!H:H)++SUMIF('믹스(잔량실사표)'!B:B,재고차이!A:A,'믹스(잔량실사표)'!H:H) -> 0 | J7: =SUM(F7:I7) -> 0 | K7: =SUMIF(SAP!#REF!,재고차이!B:B,SAP!#REF!) -> #REF! | L7: =SUMIF(주간상차!A:A,재고차이!A:A,주간상차!E:E) -> 0 | M7: =J7-K7-L7-N7+O7+Q7 -> #REF! | Q7: =SUMIF(파손품!D:D,재고차이!B:B,파손품!I:I)+SUMIF(동파파손!D:D,재고차이!B:B,동파파손!I:I) -> 0 | R7: =M7/E7 -> #REF!
A8: 1201 | B8: =VLOOKUP(A:A,제품등록!A:B,2,0) -> CA1201 | C8: =VLOOKUP(B8,제품등록!B:C,2,0) -> 캐 토닉워터250CAN 5X6 | D8: 99 | E8: 132 | F8: =SUMIF('창고1(실사표)'!B:B,재고차이!A:A,'창고1(실사표)'!F:F)*D8+SUMIF('창고2(실사표)'!B:B,재고차이!A:A,'창고2(실사표)'!F:F)*D8+SUMIF('믹스(잔량실사표)'!B:B,재고차이!A:A,'믹스(잔량실사표)'!F:F)*D8 -> 0 | G8: =SUMIF('창고1(실사표)'!B:B,재고차이!A:A,'창고1(실사표)'!E:E)*E8+SUMIF('창고2(실사표)'!B:B,재고차이!A:A,'창고2(실사표)'!E:E)*E8+SUMIF('믹스(잔량실사표)'!B:B,재고차이!A:A,'믹스(잔량실사표)'!E:E)*E8 -> 0 | H8: =SUMIF('창고1(실사표)'!B:B,재고차이!A:A,'창고1(실사표)'!G:G)+SUMIF('창고2(실사표)'!B:B,재고차이!A:A,'창고2(실사표)'!G:G)++SUMIF('믹스(잔량실사표)'!B:B,재고차이!A:A,'믹스(잔량실사표)'!G:G) -> 0 | I8: =SUMIF('창고1(실사표)'!B:B,재고차이!A:A,'창고1(실사표)'!H:H)+SUMIF('창고2(실사표)'!B:B,재고차이!A:A,'창고2(실사표)'!H:H)++SUMIF('믹스(잔량실사표)'!B:B,재고차이!A:A,'믹스(잔량실사표)'!H:H) -> 0 | J8: =SUM(F8:I8) -> 0 | K8: =SUMIF(SAP!#REF!,재고차이!B:B,SAP!#REF!) -> #REF! | L8: =SUMIF(주간상차!A:A,재고차이!A:A,주간상차!E:E) -> 0 | M8: =J8-K8-L8-N8+O8+Q8 -> #REF! | Q8: =SUMIF(파손품!D:D,재고차이!B:B,파손품!I:I)+SUMIF(동파파손!D:D,재고차이!B:B,동파파손!I:I) -> 0 | R8: =M8/E8 -> #REF!
A9: 4259 | B9: =VLOOKUP(A:A,제품등록!A:B,2,0) -> BB4259 | C9: =VLOOKUP(B9,제품등록!B:C,2,0) -> S)봉봉 포도 340CAN 4X6 | E9: 100 | F9: =SUMIF('창고1(실사표)'!B:B,재고차이!A:A,'창고1(실사표)'!F:F)*D9+SUMIF('창고2(실사표)'!B:B,재고차이!A:A,'창고2(실사표)'!F:F)*D9+SUMIF('믹스(잔량실사표)'!B:B,재고차이!A:A,'믹스(잔량실사표)'!F:F)*D9 -> 0 | G9: =SUMIF('창고1(실사표)'!B:B,재고차이!A:A,'창고1(실사표)'!E:E)*E9+SUMIF('창고2(실사표)'!B:B,재고차이!A:A,'창고2(실사표)'!E:E)*E9+SUMIF('믹스(잔량실사표)'!B:B,재고차이!A:A,'믹스(잔량실사표)'!E:E)*E9 -> 1500 | H9: =SUMIF('창고1(실사표)'!B:B,재고차이!A:A,'창고1(실사표)'!G:G)+SUMIF('창고2(실사표)'!B:B,재고차이!A:A,'창고2(실사표)'!G:G)++SUMIF('믹스(잔량실사표)'!B:B,재고차이!A:A,'믹스(잔량실사표)'!G:G) -> 67 | I9: =SUMIF('창고1(실사표)'!B:B,재고차이!A:A,'창고1(실사표)'!H:H)+SUMIF('창고2(실사표)'!B:B,재고차이!A:A,'창고2(실사표)'!H:H)++SUMIF('믹스(잔량실사표)'!B:B,재고차이!A:A,'믹스(잔량실사표)'!H:H) -> 0 | J9: =SUM(F9:I9) -> 1567 | K9: =SUMIF(SAP!B:B,재고차이!B:B,SAP!Q:Q) -> 1568 | L9: =SUMIF(주간상차!A:A,재고차이!A:A,주간상차!E:E) -> 0 | M9: =J9-K9-L9-N9+O9+Q9 -> 0 | Q9: =SUMIF(파손품!D:D,재고차이!B:B,파손품!I:I)+SUMIF(동파파손!D:D,재고차이!B:B,동파파손!I:I) -> 1 | R9: =M9/E9 -> 0
A10: 1301 | B10: =VLOOKUP(A:A,제품등록!A:B,2,0) -> CC1301 | C10: =VLOOKUP(B10,제품등록!B:C,2,0) -> 코크레드 250CAN 4X6 + 뉴진스 포토엽서 | E10: 108 | F10: =SUMIF('창고1(실사표)'!B:B,재고차이!A:A,'창고1(실사표)'!F:F)*D10+SUMIF('창고2(실사표)'!B:B,재고차이!A:A,'창고2(실사표)'!F:F)*D10+SUMIF('믹스(잔량실사표)'!B:B,재고차이!A:A,'믹스(잔량실사표)'!F:F)*D10 -> 0 | G10: =SUMIF('창고1(실사표)'!B:B,재고차이!A:A,'창고1(실사표)'!E:E)*E10+SUMIF('창고2(실사표)'!B:B,재고차이!A:A,'창고2(실사표)'!E:E)*E10+SUMIF('믹스(잔량실사표)'!B:B,재고차이!A:A,'믹스(잔량실사표)'!E:E)*E10 -> 0 | H10: =SUMIF('창고1(실사표)'!B:B,재고차이!A:A,'창고1(실사표)'!G:G)+SUMIF('창고2(실사표)'!B:B,재고차이!A:A,'창고2(실사표)'!G:G)++SUMIF('믹스(잔량실사표)'!B:B,재고차이!A:A,'믹스(잔량실사표)'!G:G) -> 0 | I10: =SUMIF('창고1(실사표)'!B:B,재고차이!A:A,'창고1(실사표)'!H:H)+SUMIF('창고2(실사표)'!B:B,재고차이!A:A,'창고2(실사표)'!H:H)++SUMIF('믹스(잔량실사표)'!B:B,재고차이!A:A,'믹스(잔량실사표)'!H:H) -> 0 | J10: =SUM(F10:I10) -> 0 | K10: =SUMIF(SAP!B:B,재고차이!B:B,SAP!Q:Q) -> 0 | L10: =SUMIF(주간상차!A:A,재고차이!A:A,주간상차!E:E) -> 0 | M10: =J10-K10-L10-N10+O10+Q10 -> 0 | Q10: =SUMIF(파손품!D:D,재고차이!B:B,파손품!I:I)+SUMIF(동파파손!D:D,재고차이!B:B,동파파손!I:I) -> 0 | R10: =M10/E10 -> 0
A11: 5700 | B11: =VLOOKUP(A:A,제품등록!A:B,2,0) -> CC5700 | C11: =VLOOKUP(B11,제품등록!B:C,2,0) -> 코카-콜라 250BTC X24 | D11: 72 | E11: 108 | F11: =SUMIF('창고1(실사표)'!B:B,재고차이!A:A,'창고1(실사표)'!F:F)*D11+SUMIF('창고2(실사표)'!B:B,재고차이!A:A,'창고2(실사표)'!F:F)*D11+SUMIF('믹스(잔량실사표)'!B:B,재고차이!A:A,'믹스(잔량실사표)'!F:F)*D11 -> 0 | G11: =SUMIF('창고1(실사표)'!B:B,재고차이!A:A,'창고1(실사표)'!E:E)*E11+SUMIF('창고2(실사표)'!B:B,재고차이!A:A,'창고2(실사표)'!E:E)*E11+SUMIF('믹스(잔량실사표)'!B:B,재고차이!A:A,'믹스(잔량실사표)'!E:E)*E11 -> 0 | H11: =SUMIF('창고1(실사표)'!B:B,재고차이!A:A,'창고1(실사표)'!G:G)+SUMIF('창고2(실사표)'!B:B,재고차이!A:A,'창고2(실사표)'!G:G)++SUMIF('믹스(잔량실사표)'!B:B,재고차이!A:A,'믹스(잔량실사표)'!G:G) -> 0 | I11: =SUMIF('창고1(실사표)'!B:B,재고차이!A:A,'창고1(실사표)'!H:H)+SUMIF('창고2(실사표)'!B:B,재고차이!A:A,'창고2(실사표)'!H:H)++SUMIF('믹스(잔량실사표)'!B:B,재고차이!A:A,'믹스(잔량실사표)'!H:H) -> 0 | J11: =SUM(F11:I11) -> 0 | K11: =SUMIF(SAP!B:B,재고차이!B:B,SAP!Q:Q) -> 0 | L11: =SUMIF(주간상차!A:A,재고차이!A:A,주간상차!E:E) -> 0 | M11: =J11-K11-L11-N11+O11+Q11 -> 0 | Q11: =SUMIF(파손품!D:D,재고차이!B:B,파손품!I:I)+SUMIF(동파파손!D:D,재고차이!B:B,동파파손!I:I) -> 0 | R11: =M11/E11 -> 0
A12: 1205 | B12: =VLOOKUP(A:A,제품등록!A:B,2,0) -> CA1205 | C12: =VLOOKUP(B12,제품등록!B:C,2,0) -> 캐나다 토닉워터 350PET 4X6 | E12: 80 | F12: =SUMIF('창고1(실사표)'!B:B,재고차이!A:A,'창고1(실사표)'!F:F)*D12+SUMIF('창고2(실사표)'!B:B,재고차이!A:A,'창고2(실사표)'!F:F)*D12+SUMIF('믹스(잔량실사표)'!B:B,재고차이!A:A,'믹스(잔량실사표)'!F:F)*D12 -> 0 | G12: =SUMIF('창고1(실사표)'!B:B,재고차이!A:A,'창고1(실사표)'!E:E)*E12+SUMIF('창고2(실사표)'!B:B,재고차이!A:A,'창고2(실사표)'!E:E)*E12+SUMIF('믹스(잔량실사표)'!B:B,재고차이!A:A,'믹스(잔량실사표)'!E:E)*E12 -> 0 | H12: =SUMIF('창고1(실사표)'!B:B,재고차이!A:A,'창고1(실사표)'!G:G)+SUMIF('창고2(실사표)'!B:B,재고차이!A:A,'창고2(실사표)'!G:G)++SUMIF('믹스(잔량실사표)'!B:B,재고차이!A:A,'믹스(잔량실사표)'!G:G) -> 0 | I12: =SUMIF('창고1(실사표)'!B:B,재고차이!A:A,'창고1(실사표)'!H:H)+SUMIF('창고2(실사표)'!B:B,재고차이!A:A,'창고2(실사표)'!H:H)++SUMIF('믹스(잔량실사표)'!B:B,재고차이!A:A,'믹스(잔량실사표)'!H:H) -> 0 | J12: =SUM(F12:I12) -> 0 | K12: =SUMIF(SAP!B:B,재고차이!B:B,SAP!Q:Q) -> 0 | L12: =SUMIF(주간상차!A:A,재고차이!A:A,주간상차!E:E) -> 0 | M12: =J12-K12-L12-N12+O12+Q12 -> 0 | Q12: =SUMIF(파손품!D:D,재고차이!B:B,파손품!I:I)+SUMIF(동파파손!D:D,재고차이!B:B,동파파손!I:I) -> 0 | R12: =M12/E12 -> 0
A13: 1206 | B13: =VLOOKUP(A:A,제품등록!A:B,2,0) -> CA1206 | C13: =VLOOKUP(B13,제품등록!B:C,2,0) -> 캐나다 진저에일 250CAN X12 | E13: 288 | F13: =SUMIF('창고1(실사표)'!B:B,재고차이!A:A,'창고1(실사표)'!F:F)*D13+SUMIF('창고2(실사표)'!B:B,재고차이!A:A,'창고2(실사표)'!F:F)*D13+SUMIF('믹스(잔량실사표)'!B:B,재고차이!A:A,'믹스(잔량실사표)'!F:F)*D13 -> 0 | G13: =SUMIF('창고1(실사표)'!B:B,재고차이!A:A,'창고1(실사표)'!E:E)*E13+SUMIF('창고2(실사표)'!B:B,재고차이!A:A,'창고2(실사표)'!E:E)*E13+SUMIF('믹스(잔량실사표)'!B:B,재고차이!A:A,'믹스(잔량실사표)'!E:E)*E13 -> 0 | H13: =SUMIF('창고1(실사표)'!B:B,재고차이!A:A,'창고1(실사표)'!G:G)+SUMIF('창고2(실사표)'!B:B,재고차이!A:A,'창고2(실사표)'!G:G)++SUMIF('믹스(잔량실사표)'!B:B,재고차이!A:A,'믹스(잔량실사표)'!G:G) -> 0 | I13: =SUMIF('창고1(실사표)'!B:B,재고차이!A:A,'창고1(실사표)'!H:H)+SUMIF('창고2(실사표)'!B:B,재고차이!A:A,'창고2(실사표)'!H:H)++SUMIF('믹스(잔량실사표)'!B:B,재고차이!A:A,'믹스(잔량실사표)'!H:H) -> 0 | J13: =SUM(F13:I13) -> 0 | K13: =SUMIF(SAP!B:B,재고차이!B:B,SAP!Q:Q) -> 0 | L13: =SUMIF(주간상차!A:A,재고차이!A:A,주간상차!E:E) -> 0 | M13: =J13-K13-L13-N13+O13+Q13 -> 0 | Q13: =SUMIF(파손품!D:D,재고차이!B:B,파손품!I:I)+SUMIF(동파파손!D:D,재고차이!B:B,동파파손!I:I) -> 0 | R13: =M13/E13 -> 0
A14: 455 | B14: =VLOOKUP(A:A,제품등록!A:B,2,0) -> CC0455 | C14: =VLOOKUP(B14,제품등록!B:C,2,0) -> 코크제로 레몬 500PET 4X6 | D14: 40 | E14: 60 | F14: =SUMIF('창고1(실사표)'!B:B,재고차이!A:A,'창고1(실사표)'!F:F)*D14+SUMIF('창고2(실사표)'!B:B,재고차이!A:A,'창고2(실사표)'!F:F)*D14+SUMIF('믹스(잔량실사표)'!B:B,재고차이!A:A,'믹스(잔량실사표)'!F:F)*D14 -> 0 | G14: =SUMIF('창고1(실사표)'!B:B,재고차이!A:A,'창고1(실사표)'!E:E)*E14+SUMIF('창고2(실사표)'!B:B,재고차이!A:A,'창고2(실사표)'!E:E)*E14+SUMIF('믹스(잔량실사표)'!B:B,재고차이!A:A,'믹스(잔량실사표)'!E:E)*E14 -> 1380 | H14: =SUMIF('창고1(실사표)'!B:B,재고차이!A:A,'창고1(실사표)'!G:G)+SUMIF('창고2(실사표)'!B:B,재고차이!A:A,'창고2(실사표)'!G:G)++SUMIF('믹스(잔량실사표)'!B:B,재고차이!A:A,'믹스(잔량실사표)'!G:G) -> 18 | I14: =SUMIF('창고1(실사표)'!B:B,재고차이!A:A,'창고1(실사표)'!H:H)+SUMIF('창고2(실사표)'!B:B,재고차이!A:A,'창고2(실사표)'!H:H)++SUMIF('믹스(잔량실사표)'!B:B,재고차이!A:A,'믹스(잔량실사표)'!H:H) -> 0 | J14: =SUM(F14:I14) -> 1398 | K14: =SUMIF(SAP!B:B,재고차이!B:B,SAP!Q:Q) -> 1398 | L14: =SUMIF(주간상차!A:A,재고차이!A:A,주간상차!E:E) -> 0 | M14: =J14-K14-L14-N14+O14+Q14 -> 0 | Q14: =SUMIF(파손품!D:D,재고차이!B:B,파손품!I:I)+SUMIF(동파파손!D:D,재고차이!B:B,동파파손!I:I) -> 0 | R14: =M14/E14 -> 0
A15: 5186 | B15: =VLOOKUP(A:A,제품등록!A:B,2,0) -> CC5186 | C15: =VLOOKUP(B15,제품등록!B:C,2,0) -> 코카콜라 490CAN 6X4 | E15: 70 | F15: =SUMIF('창고1(실사표)'!B:B,재고차이!A:A,'창고1(실사표)'!F:F)*D15+SUMIF('창고2(실사표)'!B:B,재고차이!A:A,'창고2(실사표)'!F:F)*D15+SUMIF('믹스(잔량실사표)'!B:B,재고차이!A:A,'믹스(잔량실사표)'!F:F)*D15 -> 0 | G15: =SUMIF('창고1(실사표)'!B:B,재고차이!A:A,'창고1(실사표)'!E:E)*E15+SUMIF('창고2(실사표)'!B:B,재고차이!A:A,'창고2(실사표)'!E:E)*E15+SUMIF('믹스(잔량실사표)'!B:B,재고차이!A:A,'믹스(잔량실사표)'!E:E)*E15 -> 0 | H15: =SUMIF('창고1(실사표)'!B:B,재고차이!A:A,'창고1(실사표)'!G:G)+SUMIF('창고2(실사표)'!B:B,재고차이!A:A,'창고2(실사표)'!G:G)++SUMIF('믹스(잔량실사표)'!B:B,재고차이!A:A,'믹스(잔량실사표)'!G:G) -> 0 | I15: =SUMIF('창고1(실사표)'!B:B,재고차이!A:A,'창고1(실사표)'!H:H)+SUMIF('창고2(실사표)'!B:B,재고차이!A:A,'창고2(실사표)'!H:H)++SUMIF('믹스(잔량실사표)'!B:B,재고차이!A:A,'믹스(잔량실사표)'!H:H) -> 0 | J15: =SUM(F15:I15) -> 0 | K15: =SUMIF(SAP!B:B,재고차이!B:B,SAP!Q:Q) -> 0 | L15: =SUMIF(주간상차!A:A,재고차이!A:A,주간상차!E:E) -> 0 | M15: =J15-K15-L15-N15+O15+Q15 -> 0 | Q15: =SUMIF(파손품!D:D,재고차이!B:B,파손품!I:I)+SUMIF(동파파손!D:D,재고차이!B:B,동파파손!I:I) -> 0 | R15: =M15/E15 -> 0
A16: 5189 | B16: =VLOOKUP(A:A,제품등록!A:B,2,0) -> CC5189 | C16: =VLOOKUP(B16,제품등록!B:C,2,0) -> 코크제로 490ml CAN 6X4 | E16: 70 | F16: =SUMIF('창고1(실사표)'!B:B,재고차이!A:A,'창고1(실사표)'!F:F)*D16+SUMIF('창고2(실사표)'!B:B,재고차이!A:A,'창고2(실사표)'!F:F)*D16+SUMIF('믹스(잔량실사표)'!B:B,재고차이!A:A,'믹스(잔량실사표)'!F:F)*D16 -> 0 | G16: =SUMIF('창고1(실사표)'!B:B,재고차이!A:A,'창고1(실사표)'!E:E)*E16+SUMIF('창고2(실사표)'!B:B,재고차이!A:A,'창고2(실사표)'!E:E)*E16+SUMIF('믹스(잔량실사표)'!B:B,재고차이!A:A,'믹스(잔량실사표)'!E:E)*E16 -> 0 | H16: =SUMIF('창고1(실사표)'!B:B,재고차이!A:A,'창고1(실사표)'!G:G)+SUMIF('창고2(실사표)'!B:B,재고차이!A:A,'창고2(실사표)'!G:G)++SUMIF('믹스(잔량실사표)'!B:B,재고차이!A:A,'믹스(잔량실사표)'!G:G) -> 0 | I16: =SUMIF('창고1(실사표)'!B:B,재고차이!A:A,'창고1(실사표)'!H:H)+SUMIF('창고2(실사표)'!B:B,재고차이!A:A,'창고2(실사표)'!H:H)++SUMIF('믹스(잔량실사표)'!B:B,재고차이!A:A,'믹스(잔량실사표)'!H:H) -> 0 | J16: =SUM(F16:I16) -> 0 | K16: =SUMIF(SAP!B:B,재고차이!B:B,SAP!Q:Q) -> 0 | L16: =SUMIF(주간상차!A:A,재고차이!A:A,주간상차!E:E) -> 0 | M16: =J16-K16-L16-N16+O16+Q16 -> 0 | Q16: =SUMIF(파손품!D:D,재고차이!B:B,파손품!I:I)+SUMIF(동파파손!D:D,재고차이!B:B,동파파손!I:I) -> 0 | R16: =M16/E16 -> 0
A17: 1300 | B17: =VLOOKUP(A:A,제품등록!A:B,2,0) -> CC1300 | C17: =VLOOKUP(B17,제품등록!B:C,2,0) -> 코카콜라SW 250CAN 5X6 | D17: 99 | E17: 132 | F17: =SUMIF('창고1(실사표)'!B:B,재고차이!A:A,'창고1(실사표)'!F:F)*D17+SUMIF('창고2(실사표)'!B:B,재고차이!A:A,'창고2(실사표)'!F:F)*D17+SUMIF('믹스(잔량실사표)'!B:B,재고차이!A:A,'믹스(잔량실사표)'!F:F)*D17 -> 0 | G17: =SUMIF('창고1(실사표)'!B:B,재고차이!A:A,'창고1(실사표)'!E:E)*E17+SUMIF('창고2(실사표)'!B:B,재고차이!A:A,'창고2(실사표)'!E:E)*E17+SUMIF('믹스(잔량실사표)'!B:B,재고차이!A:A,'믹스(잔량실사표)'!E:E)*E17 -> 2376 | H17: =SUMIF('창고1(실사표)'!B:B,재고차이!A:A,'창고1(실사표)'!G:G)+SUMIF('창고2(실사표)'!B:B,재고차이!A:A,'창고2(실사표)'!G:G)++SUMIF('믹스(잔량실사표)'!B:B,재고차이!A:A,'믹스(잔량실사표)'!G:G) -> 100 | I17: =SUMIF('창고1(실사표)'!B:B,재고차이!A:A,'창고1(실사표)'!H:H)+SUMIF('창고2(실사표)'!B:B,재고차이!A:A,'창고2(실사표)'!H:H)++SUMIF('믹스(잔량실사표)'!B:B,재고차이!A:A,'믹스(잔량실사표)'!H:H) -> 0 | J17: =SUM(F17:I17) -> 2476 | K17: =SUMIF(SAP!B:B,재고차이!B:B,SAP!Q:Q) -> 1816 | L17: =SUMIF(주간상차!A:A,재고차이!A:A,주간상차!E:E) -> 660 | M17: =J17-K17-L17-N17+O17+Q17 -> 0 | Q17: =SUMIF(파손품!D:D,재고차이!B:B,파손품!I:I)+SUMIF(동파파손!D:D,재고차이!B:B,동파파손!I:I) -> 0 | R17: =M17/E17 -> 0
A18: 2531 | B18: =VLOOKUP(A:A,제품등록!A:B,2,0) -> CC2531 | C18: =VLOOKUP(B18,제품등록!B:C,2,0) -> 코카콜라 350CAN 4X6 | D18: 88 | E18: 100 | F18: =SUMIF('창고1(실사표)'!B:B,재고차이!A:A,'창고1(실사표)'!F:F)*D18+SUMIF('창고2(실사표)'!B:B,재고차이!A:A,'창고2(실사표)'!F:F)*D18+SUMIF('믹스(잔량실사표)'!B:B,재고차이!A:A,'믹스(잔량실사표)'!F:F)*D18 -> 0 | G18: =SUMIF('창고1(실사표)'!B:B,재고차이!A:A,'창고1(실사표)'!E:E)*E18+SUMIF('창고2(실사표)'!B:B,재고차이!A:A,'창고2(실사표)'!E:E)*E18+SUMIF('믹스(잔량실사표)'!B:B,재고차이!A:A,'믹스(잔량실사표)'!E:E)*E18 -> 4000 | H18: =SUMIF('창고1(실사표)'!B:B,재고차이!A:A,'창고1(실사표)'!G:G)+SUMIF('창고2(실사표)'!B:B,재고차이!A:A,'창고2(실사표)'!G:G)++SUMIF('믹스(잔량실사표)'!B:B,재고차이!A:A,'믹스(잔량실사표)'!G:G) -> 80 | I18: =SUMIF('창고1(실사표)'!B:B,재고차이!A:A,'창고1(실사표)'!H:H)+SUMIF('창고2(실사표)'!B:B,재고차이!A:A,'창고2(실사표)'!H:H)++SUMIF('믹스(잔량실사표)'!B:B,재고차이!A:A,'믹스(잔량실사표)'!H:H) -> 0 | J18: =SUM(F18:I18) -> 4080 | K18: =SUMIF(SAP!B:B,재고차이!B:B,SAP!Q:Q) -> 4080 | L18: =SUMIF(주간상차!A:A,재고차이!A:A,주간상차!E:E) -> 0 | M18: =J18-K18-L18-N18+O18+Q18 -> 0 | Q18: =SUMIF(파손품!D:D,재고차이!B:B,파손품!I:I)+SUMIF(동파파손!D:D,재고차이!B:B,동파파손!I:I) -> 0 | R18: =M18/E18 -> 0
A19: 5774 | B19: =VLOOKUP(A:A,제품등록!A:B,2,0) -> CC5774 | C19: =VLOOKUP(B19,제품등록!B:C,2,0) -> 코크레드 350ml CAN 2 X 12 +타투스티커 | E19: 80 | F19: =SUMIF('창고1(실사표)'!B:B,재고차이!A:A,'창고1(실사표)'!F:F)*D19+SUMIF('창고2(실사표)'!B:B,재고차이!A:A,'창고2(실사표)'!F:F)*D19+SUMIF('믹스(잔량실사표)'!B:B,재고차이!A:A,'믹스(잔량실사표)'!F:F)*D19 -> 0 | G19: =SUMIF('창고1(실사표)'!B:B,재고차이!A:A,'창고1(실사표)'!E:E)*E19+SUMIF('창고2(실사표)'!B:B,재고차이!A:A,'창고2(실사표)'!E:E)*E19+SUMIF('믹스(잔량실사표)'!B:B,재고차이!A:A,'믹스(잔량실사표)'!E:E)*E19 -> 0 | H19: =SUMIF('창고1(실사표)'!B:B,재고차이!A:A,'창고1(실사표)'!G:G)+SUMIF('창고2(실사표)'!B:B,재고차이!A:A,'창고2(실사표)'!G:G)++SUMIF('믹스(잔량실사표)'!B:B,재고차이!A:A,'믹스(잔량실사표)'!G:G) -> 0 | I19: =SUMIF('창고1(실사표)'!B:B,재고차이!A:A,'창고1(실사표)'!H:H)+SUMIF('창고2(실사표)'!B:B,재고차이!A:A,'창고2(실사표)'!H:H)++SUMIF('믹스(잔량실사표)'!B:B,재고차이!A:A,'믹스(잔량실사표)'!H:H) -> 0 | J19: =SUM(F19:I19) -> 0 | K19: =SUMIF(SAP!B:B,재고차이!B:B,SAP!Q:Q) -> 0 | L19: =SUMIF(주간상차!A:A,재고차이!A:A,주간상차!E:E) -> 0 | M19: =J19-K19-L19-N19+O19+Q19 -> 0 | Q19: =SUMIF(파손품!D:D,재고차이!B:B,파손품!I:I)+SUMIF(동파파손!D:D,재고차이!B:B,동파파손!I:I) -> 0 | R19: =M19/E19 -> 0
A20: 4432 | B20: =VLOOKUP(A:A,제품등록!A:B,2,0) -> CC4432 | C20: =VLOOKUP(B20,제품등록!B:C,2,0) -> S)코크제로 500PET 4X6 | E20: 60 | F20: =SUMIF('창고1(실사표)'!B:B,재고차이!A:A,'창고1(실사표)'!F:F)*D20+SUMIF('창고2(실사표)'!B:B,재고차이!A:A,'창고2(실사표)'!F:F)*D20+SUMIF('믹스(잔량실사표)'!B:B,재고차이!A:A,'믹스(잔량실사표)'!F:F)*D20 -> 0 | G20: =SUMIF('창고1(실사표)'!B:B,재고차이!A:A,'창고1(실사표)'!E:E)*E20+SUMIF('창고2(실사표)'!B:B,재고차이!A:A,'창고2(실사표)'!E:E)*E20+SUMIF('믹스(잔량실사표)'!B:B,재고차이!A:A,'믹스(잔량실사표)'!E:E)*E20 -> 1140 | H20: =SUMIF('창고1(실사표)'!B:B,재고차이!A:A,'창고1(실사표)'!G:G)+SUMIF('창고2(실사표)'!B:B,재고차이!A:A,'창고2(실사표)'!G:G)++SUMIF('믹스(잔량실사표)'!B:B,재고차이!A:A,'믹스(잔량실사표)'!G:G) -> 44 | I20: =SUMIF('창고1(실사표)'!B:B,재고차이!A:A,'창고1(실사표)'!H:H)+SUMIF('창고2(실사표)'!B:B,재고차이!A:A,'창고2(실사표)'!H:H)++SUMIF('믹스(잔량실사표)'!B:B,재고차이!A:A,'믹스(잔량실사표)'!H:H) -> 0 | J20: =SUM(F20:I20) -> 1184 | K20: =SUMIF(SAP!B:B,재고차이!B:B,SAP!Q:Q) -> 224 | L20: =SUMIF(주간상차!A:A,재고차이!A:A,주간상차!E:E) -> 960 | M20: =J20-K20-L20-N20+O20+Q20 -> 0 | Q20: =SUMIF(파손품!D:D,재고차이!B:B,파손품!I:I)+SUMIF(동파파손!D:D,재고차이!B:B,동파파손!I:I) -> 0 | R20: =M20/E20 -> 0
A21: 5201 | B21: CC5201 | C21: =VLOOKUP(B21,제품등록!B:C,2,0) -> S)코크제로 제로 500PET 4X6 | E21: 60 | F21: =SUMIF('창고1(실사표)'!B:B,재고차이!A:A,'창고1(실사표)'!F:F)*D21+SUMIF('창고2(실사표)'!B:B,재고차이!A:A,'창고2(실사표)'!F:F)*D21+SUMIF('믹스(잔량실사표)'!B:B,재고차이!A:A,'믹스(잔량실사표)'!F:F)*D21 -> 0 | G21: =SUMIF('창고1(실사표)'!B:B,재고차이!A:A,'창고1(실사표)'!E:E)*E21+SUMIF('창고2(실사표)'!B:B,재고차이!A:A,'창고2(실사표)'!E:E)*E21+SUMIF('믹스(잔량실사표)'!B:B,재고차이!A:A,'믹스(잔량실사표)'!E:E)*E21 -> 840 | H21: =SUMIF('창고1(실사표)'!B:B,재고차이!A:A,'창고1(실사표)'!G:G)+SUMIF('창고2(실사표)'!B:B,재고차이!A:A,'창고2(실사표)'!G:G)++SUMIF('믹스(잔량실사표)'!B:B,재고차이!A:A,'믹스(잔량실사표)'!G:G) -> 18 | I21: =SUMIF('창고1(실사표)'!B:B,재고차이!A:A,'창고1(실사표)'!H:H)+SUMIF('창고2(실사표)'!B:B,재고차이!A:A,'창고2(실사표)'!H:H)++SUMIF('믹스(잔량실사표)'!B:B,재고차이!A:A,'믹스(잔량실사표)'!H:H) -> 0 | J21: =SUM(F21:I21) -> 858 | K21: =SUMIF(SAP!B:B,재고차이!B:B,SAP!Q:Q) -> 858 | L21: =SUMIF(주간상차!A:A,재고차이!A:A,주간상차!E:E) -> 0 | M21: =J21-K21-L21-N21+O21+Q21 -> 0 | Q21: =SUMIF(파손품!D:D,재고차이!B:B,파손품!I:I)+SUMIF(동파파손!D:D,재고차이!B:B,동파파손!I:I) -> 0 | R21: =M21/E21 -> 0
A22: 5191 | B22: =VLOOKUP(A:A,제품등록!A:B,2,0) -> CC5191 | C22: =VLOOKUP(B22,제품등록!B:C,2,0) -> 코카콜라 490CAN 6X4 | E22: 70 | F22: =SUMIF('창고1(실사표)'!B:B,재고차이!A:A,'창고1(실사표)'!F:F)*D22+SUMIF('창고2(실사표)'!B:B,재고차이!A:A,'창고2(실사표)'!F:F)*D22+SUMIF('믹스(잔량실사표)'!B:B,재고차이!A:A,'믹스(잔량실사표)'!F:F)*D22 -> 0 | G22: =SUMIF('창고1(실사표)'!B:B,재고차이!A:A,'창고1(실사표)'!E:E)*E22+SUMIF('창고2(실사표)'!B:B,재고차이!A:A,'창고2(실사표)'!E:E)*E22+SUMIF('믹스(잔량실사표)'!B:B,재고차이!A:A,'믹스(잔량실사표)'!E:E)*E22 -> 70 | H22: =SUMIF('창고1(실사표)'!B:B,재고차이!A:A,'창고1(실사표)'!G:G)+SUMIF('창고2(실사표)'!B:B,재고차이!A:A,'창고2(실사표)'!G:G)++SUMIF('믹스(잔량실사표)'!B:B,재고차이!A:A,'믹스(잔량실사표)'!G:G) -> 51 | I22: =SUMIF('창고1(실사표)'!B:B,재고차이!A:A,'창고1(실사표)'!H:H)+SUMIF('창고2(실사표)'!B:B,재고차이!A:A,'창고2(실사표)'!H:H)++SUMIF('믹스(잔량실사표)'!B:B,재고차이!A:A,'믹스(잔량실사표)'!H:H) -> 0 | J22: =SUM(F22:I22) -> 121 | K22: =SUMIF(SAP!B:B,재고차이!B:B,SAP!Q:Q) -> 121 | L22: =SUMIF(주간상차!A:A,재고차이!A:A,주간상차!E:E) -> 0 | M22: =J22-K22-L22-N22+O22+Q22 -> 0 | Q22: =SUMIF(파손품!D:D,재고차이!B:B,파손품!I:I)+SUMIF(동파파손!D:D,재고차이!B:B,동파파손!I:I) -> 0 | R22: =M22/E22 -> 0
A23: 5192 | B23: =VLOOKUP(A:A,제품등록!A:B,2,0) -> CC5192 | C23: =VLOOKUP(B23,제품등록!B:C,2,0) -> 코크제로 490ml CAN 6X4 | E23: 70 | F23: =SUMIF('창고1(실사표)'!B:B,재고차이!A:A,'창고1(실사표)'!F:F)*D23+SUMIF('창고2(실사표)'!B:B,재고차이!A:A,'창고2(실사표)'!F:F)*D23+SUMIF('믹스(잔량실사표)'!B:B,재고차이!A:A,'믹스(잔량실사표)'!F:F)*D23 -> 0 | G23: =SUMIF('창고1(실사표)'!B:B,재고차이!A:A,'창고1(실사표)'!E:E)*E23+SUMIF('창고2(실사표)'!B:B,재고차이!A:A,'창고2(실사표)'!E:E)*E23+SUMIF('믹스(잔량실사표)'!B:B,재고차이!A:A,'믹스(잔량실사표)'!E:E)*E23 -> 1120 | H23: =SUMIF('창고1(실사표)'!B:B,재고차이!A:A,'창고1(실사표)'!G:G)+SUMIF('창고2(실사표)'!B:B,재고차이!A:A,'창고2(실사표)'!G:G)++SUMIF('믹스(잔량실사표)'!B:B,재고차이!A:A,'믹스(잔량실사표)'!G:G) -> 2 | I23: =SUMIF('창고1(실사표)'!B:B,재고차이!A:A,'창고1(실사표)'!H:H)+SUMIF('창고2(실사표)'!B:B,재고차이!A:A,'창고2(실사표)'!H:H)++SUMIF('믹스(잔량실사표)'!B:B,재고차이!A:A,'믹스(잔량실사표)'!H:H) -> 0 | J23: =SUM(F23:I23) -> 1122 | K23: =SUMIF(SAP!B:B,재고차이!B:B,SAP!Q:Q) -> 1122 | L23: =SUMIF(주간상차!A:A,재고차이!A:A,주간상차!E:E) -> 0 | M23: =J23-K23-L23-N23+O23+Q23 -> 0 | Q23: =SUMIF(파손품!D:D,재고차이!B:B,파손품!I:I)+SUMIF(동파파손!D:D,재고차이!B:B,동파파손!I:I) -> 0 | R23: =M23/E23 -> 0
A24: 2520 | B24: =VLOOKUP(A:A,제품등록!A:B,2,0) -> CC2520 | C24: =VLOOKUP(B24,제품등록!B:C,2,0) -> 코카-콜라 355CAN 6X4 | E24: 100 | F24: =SUMIF('창고1(실사표)'!B:B,재고차이!A:A,'창고1(실사표)'!F:F)*D24+SUMIF('창고2(실사표)'!B:B,재고차이!A:A,'창고2(실사표)'!F:F)*D24+SUMIF('믹스(잔량실사표)'!B:B,재고차이!A:A,'믹스(잔량실사표)'!F:F)*D24 -> 0 | G24: =SUMIF('창고1(실사표)'!B:B,재고차이!A:A,'창고1(실사표)'!E:E)*E24+SUMIF('창고2(실사표)'!B:B,재고차이!A:A,'창고2(실사표)'!E:E)*E24+SUMIF('믹스(잔량실사표)'!B:B,재고차이!A:A,'믹스(잔량실사표)'!E:E)*E24 -> 0 | H24: =SUMIF('창고1(실사표)'!B:B,재고차이!A:A,'창고1(실사표)'!G:G)+SUMIF('창고2(실사표)'!B:B,재고차이!A:A,'창고2(실사표)'!G:G)++SUMIF('믹스(잔량실사표)'!B:B,재고차이!A:A,'믹스(잔량실사표)'!G:G) -> 0 | I24: =SUMIF('창고1(실사표)'!B:B,재고차이!A:A,'창고1(실사표)'!H:H)+SUMIF('창고2(실사표)'!B:B,재고차이!A:A,'창고2(실사표)'!H:H)++SUMIF('믹스(잔량실사표)'!B:B,재고차이!A:A,'믹스(잔량실사표)'!H:H) -> 0 | J24: =SUM(F24:I24) -> 0 | K24: =SUMIF(SAP!B:B,재고차이!B:B,SAP!Q:Q) -> 0 | L24: =SUMIF(주간상차!A:A,재고차이!A:A,주간상차!E:E) -> 0 | M24: =J24-K24-L24-N24+O24+Q24 -> 0 | Q24: =SUMIF(파손품!D:D,재고차이!B:B,파손품!I:I)+SUMIF(동파파손!D:D,재고차이!B:B,동파파손!I:I) -> 0 | R24: =M24/E24 -> 0
A25: 2523 | B25: =VLOOKUP(A:A,제품등록!A:B,2,0) -> CC2523 | C25: =VLOOKUP(B25,제품등록!B:C,2,0) -> 코카콜라EDLP355CAN 4X6 | E25: 100 | F25: =SUMIF('창고1(실사표)'!B:B,재고차이!A:A,'창고1(실사표)'!F:F)*D25+SUMIF('창고2(실사표)'!B:B,재고차이!A:A,'창고2(실사표)'!F:F)*D25+SUMIF('믹스(잔량실사표)'!B:B,재고차이!A:A,'믹스(잔량실사표)'!F:F)*D25 -> 0 | G25: =SUMIF('창고1(실사표)'!B:B,재고차이!A:A,'창고1(실사표)'!E:E)*E25+SUMIF('창고2(실사표)'!B:B,재고차이!A:A,'창고2(실사표)'!E:E)*E25+SUMIF('믹스(잔량실사표)'!B:B,재고차이!A:A,'믹스(잔량실사표)'!E:E)*E25 -> 0 | H25: =SUMIF('창고1(실사표)'!B:B,재고차이!A:A,'창고1(실사표)'!G:G)+SUMIF('창고2(실사표)'!B:B,재고차이!A:A,'창고2(실사표)'!G:G)++SUMIF('믹스(잔량실사표)'!B:B,재고차이!A:A,'믹스(잔량실사표)'!G:G) -> 0 | I25: =SUMIF('창고1(실사표)'!B:B,재고차이!A:A,'창고1(실사표)'!H:H)+SUMIF('창고2(실사표)'!B:B,재고차이!A:A,'창고2(실사표)'!H:H)++SUMIF('믹스(잔량실사표)'!B:B,재고차이!A:A,'믹스(잔량실사표)'!H:H) -> 0 | J25: =SUM(F25:I25) -> 0 | K25: =SUMIF(SAP!B:B,재고차이!B:B,SAP!Q:Q) -> 0 | L25: =SUMIF(주간상차!A:A,재고차이!A:A,주간상차!E:E) -> 0 | M25: =J25-K25-L25-N25+O25+Q25 -> 0 | Q25: =SUMIF(파손품!D:D,재고차이!B:B,파손품!I:I)+SUMIF(동파파손!D:D,재고차이!B:B,동파파손!I:I) -> 0 | R25: =M25/E25 -> 0
A26: 5194 | B26: =VLOOKUP(A:A,제품등록!A:B,2,0) -> CC5194 | C26: =VLOOKUP(B26,제품등록!B:C,2,0) -> S)코크제로 레몬 350CAN 4X6 | E26: 100 | F26: =SUMIF('창고1(실사표)'!B:B,재고차이!A:A,'창고1(실사표)'!F:F)*D26+SUMIF('창고2(실사표)'!B:B,재고차이!A:A,'창고2(실사표)'!F:F)*D26+SUMIF('믹스(잔량실사표)'!B:B,재고차이!A:A,'믹스(잔량실사표)'!F:F)*D26 -> 0 | G26: =SUMIF('창고1(실사표)'!B:B,재고차이!A:A,'창고1(실사표)'!E:E)*E26+SUMIF('창고2(실사표)'!B:B,재고차이!A:A,'창고2(실사표)'!E:E)*E26+SUMIF('믹스(잔량실사표)'!B:B,재고차이!A:A,'믹스(잔량실사표)'!E:E)*E26 -> 100 | H26: =SUMIF('창고1(실사표)'!B:B,재고차이!A:A,'창고1(실사표)'!G:G)+SUMIF('창고2(실사표)'!B:B,재고차이!A:A,'창고2(실사표)'!G:G)++SUMIF('믹스(잔량실사표)'!B:B,재고차이!A:A,'믹스(잔량실사표)'!G:G) -> 77 | I26: =SUMIF('창고1(실사표)'!B:B,재고차이!A:A,'창고1(실사표)'!H:H)+SUMIF('창고2(실사표)'!B:B,재고차이!A:A,'창고2(실사표)'!H:H)++SUMIF('믹스(잔량실사표)'!B:B,재고차이!A:A,'믹스(잔량실사표)'!H:H) -> 0 | J26: =SUM(F26:I26) -> 177 | K26: =SUMIF(SAP!B:B,재고차이!B:B,SAP!Q:Q) -> 177 | L26: =SUMIF(주간상차!A:A,재고차이!A:A,주간상차!E:E) -> 0 | M26: =J26-K26-L26-N26+O26+Q26 -> 0 | Q26: =SUMIF(파손품!D:D,재고차이!B:B,파손품!I:I)+SUMIF(동파파손!D:D,재고차이!B:B,동파파손!I:I) -> 0 | R26: =M26/E26 -> 0
A27: 7928 | B27: =VLOOKUP(A:A,제품등록!A:B,2,0) -> CC7928 | C27: =VLOOKUP(B27,제품등록!B:C,2,0) -> 코카콜라 500PET 2X12 +올림픽 쿨러백 | E27: 32 | F27: =SUMIF('창고1(실사표)'!B:B,재고차이!A:A,'창고1(실사표)'!F:F)*D27+SUMIF('창고2(실사표)'!B:B,재고차이!A:A,'창고2(실사표)'!F:F)*D27+SUMIF('믹스(잔량실사표)'!B:B,재고차이!A:A,'믹스(잔량실사표)'!F:F)*D27 -> 0 | G27: =SUMIF('창고1(실사표)'!B:B,재고차이!A:A,'창고1(실사표)'!E:E)*E27+SUMIF('창고2(실사표)'!B:B,재고차이!A:A,'창고2(실사표)'!E:E)*E27+SUMIF('믹스(잔량실사표)'!B:B,재고차이!A:A,'믹스(잔량실사표)'!E:E)*E27 -> 0 | H27: =SUMIF('창고1(실사표)'!B:B,재고차이!A:A,'창고1(실사표)'!G:G)+SUMIF('창고2(실사표)'!B:B,재고차이!A:A,'창고2(실사표)'!G:G)++SUMIF('믹스(잔량실사표)'!B:B,재고차이!A:A,'믹스(잔량실사표)'!G:G) -> 0 | I27: =SUMIF('창고1(실사표)'!B:B,재고차이!A:A,'창고1(실사표)'!H:H)+SUMIF('창고2(실사표)'!B:B,재고차이!A:A,'창고2(실사표)'!H:H)++SUMIF('믹스(잔량실사표)'!B:B,재고차이!A:A,'믹스(잔량실사표)'!H:H) -> 0 | J27: =SUM(F27:I27) -> 0 | K27: =SUMIF(SAP!B:B,재고차이!B:B,SAP!Q:Q) -> 0 | L27: =SUMIF(주간상차!A:A,재고차이!A:A,주간상차!E:E) -> 0 | M27: =J27-K27-L27-N27+O27+Q27 -> 0 | Q27: =SUMIF(파손품!D:D,재고차이!B:B,파손품!I:I)+SUMIF(동파파손!D:D,재고차이!B:B,동파파손!I:I) -> 0 | R27: =M27/E27 -> 0
A28: 5714 | B28: =VLOOKUP(A:A,제품등록!A:B,2,0) -> CC5714 | C28: =VLOOKUP(B28,제품등록!B:C,2,0) -> 코카콜라 벚꽃 250BTC X24 | D28: 72 | E28: 108 | F28: =SUMIF('창고1(실사표)'!B:B,재고차이!A:A,'창고1(실사표)'!F:F)*D28+SUMIF('창고2(실사표)'!B:B,재고차이!A:A,'창고2(실사표)'!F:F)*D28+SUMIF('믹스(잔량실사표)'!B:B,재고차이!A:A,'믹스(잔량실사표)'!F:F)*D28 -> 0 | G28: =SUMIF('창고1(실사표)'!B:B,재고차이!A:A,'창고1(실사표)'!E:E)*E28+SUMIF('창고2(실사표)'!B:B,재고차이!A:A,'창고2(실사표)'!E:E)*E28+SUMIF('믹스(잔량실사표)'!B:B,재고차이!A:A,'믹스(잔량실사표)'!E:E)*E28 -> 0 | H28: =SUMIF('창고1(실사표)'!B:B,재고차이!A:A,'창고1(실사표)'!G:G)+SUMIF('창고2(실사표)'!B:B,재고차이!A:A,'창고2(실사표)'!G:G)++SUMIF('믹스(잔량실사표)'!B:B,재고차이!A:A,'믹스(잔량실사표)'!G:G) -> 0 | I28: =SUMIF('창고1(실사표)'!B:B,재고차이!A:A,'창고1(실사표)'!H:H)+SUMIF('창고2(실사표)'!B:B,재고차이!A:A,'창고2(실사표)'!H:H)++SUMIF('믹스(잔량실사표)'!B:B,재고차이!A:A,'믹스(잔량실사표)'!H:H) -> 0 | J28: =SUM(F28:I28) -> 0 | K28: =SUMIF(SAP!B:B,재고차이!B:B,SAP!Q:Q) -> 0 | L28: =SUMIF(주간상차!A:A,재고차이!A:A,주간상차!E:E) -> 0 | M28: =J28-K28-L28-N28+O28+Q28 -> 0 | Q28: =SUMIF(파손품!D:D,재고차이!B:B,파손품!I:I)+SUMIF(동파파손!D:D,재고차이!B:B,동파파손!I:I) -> 0 | R28: =M28/E28 -> 0
A29: 5200 | B29: =VLOOKUP(A:A,제품등록!A:B,2,0) -> CC5200 | C29: =VLOOKUP(B29,제품등록!B:C,2,0) -> 코카콜라 900PET 2X6 | E29: 65 | F29: =SUMIF('창고1(실사표)'!B:B,재고차이!A:A,'창고1(실사표)'!F:F)*D29+SUMIF('창고2(실사표)'!B:B,재고차이!A:A,'창고2(실사표)'!F:F)*D29+SUMIF('믹스(잔량실사표)'!B:B,재고차이!A:A,'믹스(잔량실사표)'!F:F)*D29 -> 0 | G29: =SUMIF('창고1(실사표)'!B:B,재고차이!A:A,'창고1(실사표)'!E:E)*E29+SUMIF('창고2(실사표)'!B:B,재고차이!A:A,'창고2(실사표)'!E:E)*E29+SUMIF('믹스(잔량실사표)'!B:B,재고차이!A:A,'믹스(잔량실사표)'!E:E)*E29 -> 0 | H29: =SUMIF('창고1(실사표)'!B:B,재고차이!A:A,'창고1(실사표)'!G:G)+SUMIF('창고2(실사표)'!B:B,재고차이!A:A,'창고2(실사표)'!G:G)++SUMIF('믹스(잔량실사표)'!B:B,재고차이!A:A,'믹스(잔량실사표)'!G:G) -> 49 | I29: =SUMIF('창고1(실사표)'!B:B,재고차이!A:A,'창고1(실사표)'!H:H)+SUMIF('창고2(실사표)'!B:B,재고차이!A:A,'창고2(실사표)'!H:H)++SUMIF('믹스(잔량실사표)'!B:B,재고차이!A:A,'믹스(잔량실사표)'!H:H) -> 0 | J29: =SUM(F29:I29) -> 49 | K29: =SUMIF(SAP!B:B,재고차이!B:B,SAP!Q:Q) -> 49 | L29: =SUMIF(주간상차!A:A,재고차이!A:A,주간상차!E:E) -> 0 | M29: =J29-K29-L29-N29+O29+Q29 -> 0 | Q29: =SUMIF(파손품!D:D,재고차이!B:B,파손품!I:I)+SUMIF(동파파손!D:D,재고차이!B:B,동파파손!I:I) -> 0 | R29: =M29/E29 -> 0
A30: 5769 | B30: =VLOOKUP(A:A,제품등록!A:B,2,0) -> CC5769 | C30: =VLOOKUP(B30,제품등록!B:C,2,0) -> 코크제로 제로 350CAN 4X6 | E30: 100 | F30: =SUMIF('창고1(실사표)'!B:B,재고차이!A:A,'창고1(실사표)'!F:F)*D30+SUMIF('창고2(실사표)'!B:B,재고차이!A:A,'창고2(실사표)'!F:F)*D30+SUMIF('믹스(잔량실사표)'!B:B,재고차이!A:A,'믹스(잔량실사표)'!F:F)*D30 -> 0 | G30: =SUMIF('창고1(실사표)'!B:B,재고차이!A:A,'창고1(실사표)'!E:E)*E30+SUMIF('창고2(실사표)'!B:B,재고차이!A:A,'창고2(실사표)'!E:E)*E30+SUMIF('믹스(잔량실사표)'!B:B,재고차이!A:A,'믹스(잔량실사표)'!E:E)*E30 -> 0 | H30: =SUMIF('창고1(실사표)'!B:B,재고차이!A:A,'창고1(실사표)'!G:G)+SUMIF('창고2(실사표)'!B:B,재고차이!A:A,'창고2(실사표)'!G:G)++SUMIF('믹스(잔량실사표)'!B:B,재고차이!A:A,'믹스(잔량실사표)'!G:G) -> 50 | I30: =SUMIF('창고1(실사표)'!B:B,재고차이!A:A,'창고1(실사표)'!H:H)+SUMIF('창고2(실사표)'!B:B,재고차이!A:A,'창고2(실사표)'!H:H)++SUMIF('믹스(잔량실사표)'!B:B,재고차이!A:A,'믹스(잔량실사표)'!H:H) -> 0 | J30: =SUM(F30:I30) -> 50 | K30: =SUMIF(SAP!B:B,재고차이!B:B,SAP!Q:Q) -> 50 | L30: =SUMIF(주간상차!A:A,재고차이!A:A,주간상차!E:E) -> 0 | M30: =J30-K30-L30-N30+O30+Q30 -> 0 | Q30: =SUMIF(파손품!D:D,재고차이!B:B,파손품!I:I)+SUMIF(동파파손!D:D,재고차이!B:B,동파파손!I:I) -> 0 | R30: =M30/E30 -> 0
A31: 5771 | B31: =VLOOKUP(A:A,제품등록!A:B,2,0) -> CC5771 | C31: =VLOOKUP(B31,제품등록!B:C,2,0) -> 코크제로 제로 250CAN 5X6 | D31: 99 | E31: 132 | F31: =SUMIF('창고1(실사표)'!B:B,재고차이!A:A,'창고1(실사표)'!F:F)*D31+SUMIF('창고2(실사표)'!B:B,재고차이!A:A,'창고2(실사표)'!F:F)*D31+SUMIF('믹스(잔량실사표)'!B:B,재고차이!A:A,'믹스(잔량실사표)'!F:F)*D31 -> 0 | G31: =SUMIF('창고1(실사표)'!B:B,재고차이!A:A,'창고1(실사표)'!E:E)*E31+SUMIF('창고2(실사표)'!B:B,재고차이!A:A,'창고2(실사표)'!E:E)*E31+SUMIF('믹스(잔량실사표)'!B:B,재고차이!A:A,'믹스(잔량실사표)'!E:E)*E31 -> 264 | H31: =SUMIF('창고1(실사표)'!B:B,재고차이!A:A,'창고1(실사표)'!G:G)+SUMIF('창고2(실사표)'!B:B,재고차이!A:A,'창고2(실사표)'!G:G)++SUMIF('믹스(잔량실사표)'!B:B,재고차이!A:A,'믹스(잔량실사표)'!G:G) -> 103 | I31: =SUMIF('창고1(실사표)'!B:B,재고차이!A:A,'창고1(실사표)'!H:H)+SUMIF('창고2(실사표)'!B:B,재고차이!A:A,'창고2(실사표)'!H:H)++SUMIF('믹스(잔량실사표)'!B:B,재고차이!A:A,'믹스(잔량실사표)'!H:H) -> 0 | J31: =SUM(F31:I31) -> 367 | K31: =SUMIF(SAP!B:B,재고차이!B:B,SAP!Q:Q) -> 367 | L31: =SUMIF(주간상차!A:A,재고차이!A:A,주간상차!E:E) -> 0 | M31: =J31-K31-L31-N31+O31+Q31 -> 0 | Q31: =SUMIF(파손품!D:D,재고차이!B:B,파손품!I:I)+SUMIF(동파파손!D:D,재고차이!B:B,동파파손!I:I) -> 0 | R31: =M31/E31 -> 0
A32: 5777 | B32: =VLOOKUP(A:A,제품등록!A:B,2,0) -> CC5777 | C32: =VLOOKUP(B32,제품등록!B:C,2,0) -> 코크제로 350CAN 4X6 | E32: 100 | F32: =SUMIF('창고1(실사표)'!B:B,재고차이!A:A,'창고1(실사표)'!F:F)*D32+SUMIF('창고2(실사표)'!B:B,재고차이!A:A,'창고2(실사표)'!F:F)*D32+SUMIF('믹스(잔량실사표)'!B:B,재고차이!A:A,'믹스(잔량실사표)'!F:F)*D32 -> 0 | G32: =SUMIF('창고1(실사표)'!B:B,재고차이!A:A,'창고1(실사표)'!E:E)*E32+SUMIF('창고2(실사표)'!B:B,재고차이!A:A,'창고2(실사표)'!E:E)*E32+SUMIF('믹스(잔량실사표)'!B:B,재고차이!A:A,'믹스(잔량실사표)'!E:E)*E32 -> 600 | H32: =SUMIF('창고1(실사표)'!B:B,재고차이!A:A,'창고1(실사표)'!G:G)+SUMIF('창고2(실사표)'!B:B,재고차이!A:A,'창고2(실사표)'!G:G)++SUMIF('믹스(잔량실사표)'!B:B,재고차이!A:A,'믹스(잔량실사표)'!G:G) -> 74 | I32: =SUMIF('창고1(실사표)'!B:B,재고차이!A:A,'창고1(실사표)'!H:H)+SUMIF('창고2(실사표)'!B:B,재고차이!A:A,'창고2(실사표)'!H:H)++SUMIF('믹스(잔량실사표)'!B:B,재고차이!A:A,'믹스(잔량실사표)'!H:H) -> 0 | J32: =SUM(F32:I32) -> 674 | K32: =SUMIF(SAP!B:B,재고차이!B:B,SAP!Q:Q) -> 474 | L32: =SUMIF(주간상차!A:A,재고차이!A:A,주간상차!E:E) -> 200 | M32: =J32-K32-L32-N32+O32+Q32 -> 0 | Q32: =SUMIF(파손품!D:D,재고차이!B:B,파손품!I:I)+SUMIF(동파파손!D:D,재고차이!B:B,동파파손!I:I) -> 0 | R32: =M32/E32 -> 0
A33: 5782 | B33: =VLOOKUP(A:A,제품등록!A:B,2,0) -> CC5782 | C33: =VLOOKUP(B33,제품등록!B:C,2,0) -> 코크제로 체리 500PET 4X6 | D33: 40 | E33: 60 | F33: =SUMIF('창고1(실사표)'!B:B,재고차이!A:A,'창고1(실사표)'!F:F)*D33+SUMIF('창고2(실사표)'!B:B,재고차이!A:A,'창고2(실사표)'!F:F)*D33+SUMIF('믹스(잔량실사표)'!B:B,재고차이!A:A,'믹스(잔량실사표)'!F:F)*D33 -> 0 | G33: =SUMIF('창고1(실사표)'!B:B,재고차이!A:A,'창고1(실사표)'!E:E)*E33+SUMIF('창고2(실사표)'!B:B,재고차이!A:A,'창고2(실사표)'!E:E)*E33+SUMIF('믹스(잔량실사표)'!B:B,재고차이!A:A,'믹스(잔량실사표)'!E:E)*E33 -> 780 | H33: =SUMIF('창고1(실사표)'!B:B,재고차이!A:A,'창고1(실사표)'!G:G)+SUMIF('창고2(실사표)'!B:B,재고차이!A:A,'창고2(실사표)'!G:G)++SUMIF('믹스(잔량실사표)'!B:B,재고차이!A:A,'믹스(잔량실사표)'!G:G) -> 14 | I33: =SUMIF('창고1(실사표)'!B:B,재고차이!A:A,'창고1(실사표)'!H:H)+SUMIF('창고2(실사표)'!B:B,재고차이!A:A,'창고2(실사표)'!H:H)++SUMIF('믹스(잔량실사표)'!B:B,재고차이!A:A,'믹스(잔량실사표)'!H:H) -> 0 | J33: =SUM(F33:I33) -> 794 | K33: =SUMIF(SAP!B:B,재고차이!B:B,SAP!Q:Q) -> 794 | L33: =SUMIF(주간상차!A:A,재고차이!A:A,주간상차!E:E) -> 0 | M33: =J33-K33-L33-N33+O33+Q33 -> 0 | Q33: =SUMIF(파손품!D:D,재고차이!B:B,파손품!I:I)+SUMIF(동파파손!D:D,재고차이!B:B,동파파손!I:I) -> 0 | R33: =M33/E33 -> 0
A34: 8279 | B34: =VLOOKUP(A:A,제품등록!A:B,2,0) -> CC8279 | C34: =VLOOKUP(B34,제품등록!B:C,2,0) -> 코크제로 355CAN 4X6 | E34: 100 | F34: =SUMIF('창고1(실사표)'!B:B,재고차이!A:A,'창고1(실사표)'!F:F)*D34+SUMIF('창고2(실사표)'!B:B,재고차이!A:A,'창고2(실사표)'!F:F)*D34+SUMIF('믹스(잔량실사표)'!B:B,재고차이!A:A,'믹스(잔량실사표)'!F:F)*D34 -> 0 | G34: =SUMIF('창고1(실사표)'!B:B,재고차이!A:A,'창고1(실사표)'!E:E)*E34+SUMIF('창고2(실사표)'!B:B,재고차이!A:A,'창고2(실사표)'!E:E)*E34+SUMIF('믹스(잔량실사표)'!B:B,재고차이!A:A,'믹스(잔량실사표)'!E:E)*E34 -> 0 | H34: =SUMIF('창고1(실사표)'!B:B,재고차이!A:A,'창고1(실사표)'!G:G)+SUMIF('창고2(실사표)'!B:B,재고차이!A:A,'창고2(실사표)'!G:G)++SUMIF('믹스(잔량실사표)'!B:B,재고차이!A:A,'믹스(잔량실사표)'!G:G) -> 0 | I34: =SUMIF('창고1(실사표)'!B:B,재고차이!A:A,'창고1(실사표)'!H:H)+SUMIF('창고2(실사표)'!B:B,재고차이!A:A,'창고2(실사표)'!H:H)++SUMIF('믹스(잔량실사표)'!B:B,재고차이!A:A,'믹스(잔량실사표)'!H:H) -> 0 | J34: =SUM(F34:I34) -> 0 | K34: =SUMIF(SAP!B:B,재고차이!B:B,SAP!Q:Q) -> 0 | L34: =SUMIF(주간상차!A:A,재고차이!A:A,주간상차!E:E) -> 0 | M34: =J34-K34-L34-N34+O34+Q34 -> 0 | Q34: =SUMIF(파손품!D:D,재고차이!B:B,파손품!I:I)+SUMIF(동파파손!D:D,재고차이!B:B,동파파손!I:I) -> 0 | R34: =M34/E34 -> 0
A35: 6676 | B35: =VLOOKUP(A:A,제품등록!A:B,2,0) -> CC6676 | C35: =VLOOKUP(B35,제품등록!B:C,2,0) -> S)코카콜라 500PET 4X6 | D35: 40 | E35: 60 | F35: =SUMIF('창고1(실사표)'!B:B,재고차이!A:A,'창고1(실사표)'!F:F)*D35+SUMIF('창고2(실사표)'!B:B,재고차이!A:A,'창고2(실사표)'!F:F)*D35+SUMIF('믹스(잔량실사표)'!B:B,재고차이!A:A,'믹스(잔량실사표)'!F:F)*D35 -> 0 | G35: =SUMIF('창고1(실사표)'!B:B,재고차이!A:A,'창고1(실사표)'!E:E)*E35+SUMIF('창고2(실사표)'!B:B,재고차이!A:A,'창고2(실사표)'!E:E)*E35+SUMIF('믹스(잔량실사표)'!B:B,재고차이!A:A,'믹스(잔량실사표)'!E:E)*E35 -> 1380 | H35: =SUMIF('창고1(실사표)'!B:B,재고차이!A:A,'창고1(실사표)'!G:G)+SUMIF('창고2(실사표)'!B:B,재고차이!A:A,'창고2(실사표)'!G:G)++SUMIF('믹스(잔량실사표)'!B:B,재고차이!A:A,'믹스(잔량실사표)'!G:G) -> 57 | I35: =SUMIF('창고1(실사표)'!B:B,재고차이!A:A,'창고1(실사표)'!H:H)+SUMIF('창고2(실사표)'!B:B,재고차이!A:A,'창고2(실사표)'!H:H)++SUMIF('믹스(잔량실사표)'!B:B,재고차이!A:A,'믹스(잔량실사표)'!H:H) -> 0 | J35: =SUM(F35:I35) -> 1437 | K35: =SUMIF(SAP!B:B,재고차이!B:B,SAP!Q:Q) -> 717 | L35: =SUMIF(주간상차!A:A,재고차이!A:A,주간상차!E:E) -> 720 | M35: =J35-K35-L35-N35+O35+Q35 -> 0 | Q35: =SUMIF(파손품!D:D,재고차이!B:B,파손품!I:I)+SUMIF(동파파손!D:D,재고차이!B:B,동파파손!I:I) -> 0 | R35: =M35/E35 -> 0
A36: 454 | B36: =VLOOKUP(A:A,제품등록!A:B,2,0) -> CC0454 | C36: =VLOOKUP(B36,제품등록!B:C,2,0) -> 코크 제로 레몬 355CAN 4X6 | E36: 100 | F36: =SUMIF('창고1(실사표)'!B:B,재고차이!A:A,'창고1(실사표)'!F:F)*D36+SUMIF('창고2(실사표)'!B:B,재고차이!A:A,'창고2(실사표)'!F:F)*D36+SUMIF('믹스(잔량실사표)'!B:B,재고차이!A:A,'믹스(잔량실사표)'!F:F)*D36 -> 0 | G36: =SUMIF('창고1(실사표)'!B:B,재고차이!A:A,'창고1(실사표)'!E:E)*E36+SUMIF('창고2(실사표)'!B:B,재고차이!A:A,'창고2(실사표)'!E:E)*E36+SUMIF('믹스(잔량실사표)'!B:B,재고차이!A:A,'믹스(잔량실사표)'!E:E)*E36 -> 0 | H36: =SUMIF('창고1(실사표)'!B:B,재고차이!A:A,'창고1(실사표)'!G:G)+SUMIF('창고2(실사표)'!B:B,재고차이!A:A,'창고2(실사표)'!G:G)++SUMIF('믹스(잔량실사표)'!B:B,재고차이!A:A,'믹스(잔량실사표)'!G:G) -> 0 | I36: =SUMIF('창고1(실사표)'!B:B,재고차이!A:A,'창고1(실사표)'!H:H)+SUMIF('창고2(실사표)'!B:B,재고차이!A:A,'창고2(실사표)'!H:H)++SUMIF('믹스(잔량실사표)'!B:B,재고차이!A:A,'믹스(잔량실사표)'!H:H) -> 0 | J36: =SUM(F36:I36) -> 0 | K36: =SUMIF(SAP!B:B,재고차이!B:B,SAP!Q:Q) -> 0 | L36: =SUMIF(주간상차!A:A,재고차이!A:A,주간상차!E:E) -> 0 | M36: =J36-K36-L36-N36+O36+Q36 -> 0 | Q36: =SUMIF(파손품!D:D,재고차이!B:B,파손품!I:I)+SUMIF(동파파손!D:D,재고차이!B:B,동파파손!I:I) -> 0 | R36: =M36/E36 -> 0
A37: 7923 | B37: =VLOOKUP(A:A,제품등록!A:B,2,0) -> CC7923 | C37: =VLOOKUP(B37,제품등록!B:C,2,0) -> S)코카-콜라1.5PET 2X6 | D37: 32 | E37: 44 | F37: =SUMIF('창고1(실사표)'!B:B,재고차이!A:A,'창고1(실사표)'!F:F)*D37+SUMIF('창고2(실사표)'!B:B,재고차이!A:A,'창고2(실사표)'!F:F)*D37+SUMIF('믹스(잔량실사표)'!B:B,재고차이!A:A,'믹스(잔량실사표)'!F:F)*D37 -> 0 | G37: =SUMIF('창고1(실사표)'!B:B,재고차이!A:A,'창고1(실사표)'!E:E)*E37+SUMIF('창고2(실사표)'!B:B,재고차이!A:A,'창고2(실사표)'!E:E)*E37+SUMIF('믹스(잔량실사표)'!B:B,재고차이!A:A,'믹스(잔량실사표)'!E:E)*E37 -> 1320 | H37: =SUMIF('창고1(실사표)'!B:B,재고차이!A:A,'창고1(실사표)'!G:G)+SUMIF('창고2(실사표)'!B:B,재고차이!A:A,'창고2(실사표)'!G:G)++SUMIF('믹스(잔량실사표)'!B:B,재고차이!A:A,'믹스(잔량실사표)'!G:G) -> 14 | I37: =SUMIF('창고1(실사표)'!B:B,재고차이!A:A,'창고1(실사표)'!H:H)+SUMIF('창고2(실사표)'!B:B,재고차이!A:A,'창고2(실사표)'!H:H)++SUMIF('믹스(잔량실사표)'!B:B,재고차이!A:A,'믹스(잔량실사표)'!H:H) -> 0 | J37: =SUM(F37:I37) -> 1334 | K37: =SUMIF(SAP!B:B,재고차이!B:B,SAP!Q:Q) -> 454 | L37: =SUMIF(주간상차!A:A,재고차이!A:A,주간상차!E:E) -> 880 | M37: =J37-K37-L37-N37+O37+Q37 -> 0 | Q37: =SUMIF(파손품!D:D,재고차이!B:B,파손품!I:I)+SUMIF(동파파손!D:D,재고차이!B:B,동파파손!I:I) -> 0 | R37: =M37/E37 -> 0
A38: 5778 | B38: =VLOOKUP(A:A,제품등록!A:B,2,0) -> CC5778 | C38: =VLOOKUP(B38,제품등록!B:C,2,0) -> 코크제로 한류 355CAN 4X6 | E38: 100 | F38: =SUMIF('창고1(실사표)'!B:B,재고차이!A:A,'창고1(실사표)'!F:F)*D38+SUMIF('창고2(실사표)'!B:B,재고차이!A:A,'창고2(실사표)'!F:F)*D38+SUMIF('믹스(잔량실사표)'!B:B,재고차이!A:A,'믹스(잔량실사표)'!F:F)*D38 -> 0 | G38: =SUMIF('창고1(실사표)'!B:B,재고차이!A:A,'창고1(실사표)'!E:E)*E38+SUMIF('창고2(실사표)'!B:B,재고차이!A:A,'창고2(실사표)'!E:E)*E38+SUMIF('믹스(잔량실사표)'!B:B,재고차이!A:A,'믹스(잔량실사표)'!E:E)*E38 -> 0 | H38: =SUMIF('창고1(실사표)'!B:B,재고차이!A:A,'창고1(실사표)'!G:G)+SUMIF('창고2(실사표)'!B:B,재고차이!A:A,'창고2(실사표)'!G:G)++SUMIF('믹스(잔량실사표)'!B:B,재고차이!A:A,'믹스(잔량실사표)'!G:G) -> 0 | I38: =SUMIF('창고1(실사표)'!B:B,재고차이!A:A,'창고1(실사표)'!H:H)+SUMIF('창고2(실사표)'!B:B,재고차이!A:A,'창고2(실사표)'!H:H)++SUMIF('믹스(잔량실사표)'!B:B,재고차이!A:A,'믹스(잔량실사표)'!H:H) -> 0 | J38: =SUM(F38:I38) -> 0 | K38: =SUMIF(SAP!B:B,재고차이!B:B,SAP!Q:Q) -> 0 | L38: =SUMIF(주간상차!A:A,재고차이!A:A,주간상차!E:E) -> 0 | M38: =J38-K38-L38-N38+O38+Q38 -> 0 | Q38: =SUMIF(파손품!D:D,재고차이!B:B,파손품!I:I)+SUMIF(동파파손!D:D,재고차이!B:B,동파파손!I:I) -> 0 | R38: =M38/E38 -> 0
A39: 5770 | B39: =VLOOKUP(A:A,제품등록!A:B,2,0) -> CC5770 | C39: =VLOOKUP(B39,제품등록!B:C,2,0) -> 코크제로 레전드 355CAN 4X6 | E39: 100 | F39: =SUMIF('창고1(실사표)'!B:B,재고차이!A:A,'창고1(실사표)'!F:F)*D39+SUMIF('창고2(실사표)'!B:B,재고차이!A:A,'창고2(실사표)'!F:F)*D39+SUMIF('믹스(잔량실사표)'!B:B,재고차이!A:A,'믹스(잔량실사표)'!F:F)*D39 -> 0 | G39: =SUMIF('창고1(실사표)'!B:B,재고차이!A:A,'창고1(실사표)'!E:E)*E39+SUMIF('창고2(실사표)'!B:B,재고차이!A:A,'창고2(실사표)'!E:E)*E39+SUMIF('믹스(잔량실사표)'!B:B,재고차이!A:A,'믹스(잔량실사표)'!E:E)*E39 -> 0 | H39: =SUMIF('창고1(실사표)'!B:B,재고차이!A:A,'창고1(실사표)'!G:G)+SUMIF('창고2(실사표)'!B:B,재고차이!A:A,'창고2(실사표)'!G:G)++SUMIF('믹스(잔량실사표)'!B:B,재고차이!A:A,'믹스(잔량실사표)'!G:G) -> 0 | I39: =SUMIF('창고1(실사표)'!B:B,재고차이!A:A,'창고1(실사표)'!H:H)+SUMIF('창고2(실사표)'!B:B,재고차이!A:A,'창고2(실사표)'!H:H)++SUMIF('믹스(잔량실사표)'!B:B,재고차이!A:A,'믹스(잔량실사표)'!H:H) -> 0 | J39: =SUM(F39:I39) -> 0 | K39: =SUMIF(SAP!B:B,재고차이!B:B,SAP!Q:Q) -> 0 | L39: =SUMIF(주간상차!A:A,재고차이!A:A,주간상차!E:E) -> 0 | M39: =J39-K39-L39-N39+O39+Q39 -> 0 | Q39: =SUMIF(파손품!D:D,재고차이!B:B,파손품!I:I)+SUMIF(동파파손!D:D,재고차이!B:B,동파파손!I:I) -> 0 | R39: =M39/E39 -> 0
A40: 7539 | B40: =VLOOKUP(A:A,제품등록!A:B,2,0) -> CC7539 | C40: =VLOOKUP(B40,제품등록!B:C,2,0) -> 코크제로 스타더스트 355CAN 4X6 | E40: 100 | F40: =SUMIF('창고1(실사표)'!B:B,재고차이!A:A,'창고1(실사표)'!F:F)*D40+SUMIF('창고2(실사표)'!B:B,재고차이!A:A,'창고2(실사표)'!F:F)*D40+SUMIF('믹스(잔량실사표)'!B:B,재고차이!A:A,'믹스(잔량실사표)'!F:F)*D40 -> 0 | G40: =SUMIF('창고1(실사표)'!B:B,재고차이!A:A,'창고1(실사표)'!E:E)*E40+SUMIF('창고2(실사표)'!B:B,재고차이!A:A,'창고2(실사표)'!E:E)*E40+SUMIF('믹스(잔량실사표)'!B:B,재고차이!A:A,'믹스(잔량실사표)'!E:E)*E40 -> 0 | H40: =SUMIF('창고1(실사표)'!B:B,재고차이!A:A,'창고1(실사표)'!G:G)+SUMIF('창고2(실사표)'!B:B,재고차이!A:A,'창고2(실사표)'!G:G)++SUMIF('믹스(잔량실사표)'!B:B,재고차이!A:A,'믹스(잔량실사표)'!G:G) -> 0 | I40: =SUMIF('창고1(실사표)'!B:B,재고차이!A:A,'창고1(실사표)'!H:H)+SUMIF('창고2(실사표)'!B:B,재고차이!A:A,'창고2(실사표)'!H:H)++SUMIF('믹스(잔량실사표)'!B:B,재고차이!A:A,'믹스(잔량실사표)'!H:H) -> 0 | J40: =SUM(F40:I40) -> 0 | K40: =SUMIF(SAP!B:B,재고차이!B:B,SAP!Q:Q) -> 0 | L40: =SUMIF(주간상차!A:A,재고차이!A:A,주간상차!E:E) -> 0 | M40: =J40-K40-L40-N40+O40+Q40 -> 0 | Q40: =SUMIF(파손품!D:D,재고차이!B:B,파손품!I:I)+SUMIF(동파파손!D:D,재고차이!B:B,동파파손!I:I) -> 0 | R40: =M40/E40 -> 0
A41: 8273 | B41: =VLOOKUP(A:A,제품등록!A:B,2,0) -> CC8273 | C41: =VLOOKUP(B41,제품등록!B:C,2,0) -> 코크 제로 250CAN 5X6 | D41: 99 | E41: 132 | F41: =SUMIF('창고1(실사표)'!B:B,재고차이!A:A,'창고1(실사표)'!F:F)*D41+SUMIF('창고2(실사표)'!B:B,재고차이!A:A,'창고2(실사표)'!F:F)*D41+SUMIF('믹스(잔량실사표)'!B:B,재고차이!A:A,'믹스(잔량실사표)'!F:F)*D41 -> 0 | G41: =SUMIF('창고1(실사표)'!B:B,재고차이!A:A,'창고1(실사표)'!E:E)*E41+SUMIF('창고2(실사표)'!B:B,재고차이!A:A,'창고2(실사표)'!E:E)*E41+SUMIF('믹스(잔량실사표)'!B:B,재고차이!A:A,'믹스(잔량실사표)'!E:E)*E41 -> 0 | H41: =SUMIF('창고1(실사표)'!B:B,재고차이!A:A,'창고1(실사표)'!G:G)+SUMIF('창고2(실사표)'!B:B,재고차이!A:A,'창고2(실사표)'!G:G)++SUMIF('믹스(잔량실사표)'!B:B,재고차이!A:A,'믹스(잔량실사표)'!G:G) -> 14 | I41: =SUMIF('창고1(실사표)'!B:B,재고차이!A:A,'창고1(실사표)'!H:H)+SUMIF('창고2(실사표)'!B:B,재고차이!A:A,'창고2(실사표)'!H:H)++SUMIF('믹스(잔량실사표)'!B:B,재고차이!A:A,'믹스(잔량실사표)'!H:H) -> 0 | J41: =SUM(F41:I41) -> 14 | K41: =SUMIF(SAP!B:B,재고차이!B:B,SAP!Q:Q) -> 14 | L41: =SUMIF(주간상차!A:A,재고차이!A:A,주간상차!E:E) -> 0 | M41: =J41-K41-L41-N41+O41+Q41 -> 0 | Q41: =SUMIF(파손품!D:D,재고차이!B:B,파손품!I:I)+SUMIF(동파파손!D:D,재고차이!B:B,동파파손!I:I) -> 0 | R41: =M41/E41 -> 0
...

Sheet 창고1(실사표)
H1: 조사일 | I1: =TODAY() -> 46008 | N1: =100%-N2 -> 0.25
B2: 제품코드 | C2: SAP코드 | D2: Brand Name | E2: 아주 | F2: 940P | G2: 잔량 | H2: 보류재고 | I2: 소비기한 | J2: 홀딩테그 | K2: 75% 사용가능 | L2: 소비기한 | M2: 생산일자 | N2: 0.75 | O2: 사용가능 | P2: 사용가능일수 75%
A3: =ROW()-2 -> 1 | B3: 7949 | C3: =VLOOKUP(B:B,재고차이!A:B,2,0) -> MM7949 | D3: =VLOOKUP(C:C,재고차이!B:C,2,0) -> 미닛 오+포+알 180NRB 3X12 | I3: 46089 | K3: =+P3 -> -123.75 | L3: =IF(I3="","",SUMIF(제품등록!B:B,'창고1(실사표)'!C:C,제품등록!F:F)) -> 273 | M3: =IF(I3=0,"",I3-L3) -> 45816 | N3: =IF(L3="","",L3*상미75) -> 68.25 | O3: =IF(M3="","",M3+N3) -> 45884.25 | P3: =IF(O3="","",O3-$I$1) -> -123.75
A4: =ROW()-2 -> 2 | B4: 6509 | C4: =VLOOKUP(B:B,재고차이!A:B,2,0) -> MM6509 | D4: =VLOOKUP(C:C,재고차이!B:C,2,0) -> S)MM오리지널0R100 1.5P 2X6 | E4: 13 | I4: 46110 | K4: =+P4 -> -102.75 | L4: =IF(I4="","",SUMIF(제품등록!B:B,'창고1(실사표)'!C:C,제품등록!F:F)) -> 273 | M4: =IF(I4=0,"",I4-L4) -> 45837 | N4: =IF(L4="","",L4*상미75) -> 68.25 | O4: =IF(M4="","",M4+N4) -> 45905.25 | P4: =IF(O4="","",O4-$I$1) -> -102.75
A5: =ROW()-2 -> 3 | B5: 6705 | C5: =VLOOKUP(B:B,재고차이!A:B,2,0) -> MM6705 | D5: =VLOOKUP(C:C,재고차이!B:C,2,0) -> S)MM오리지널OR100 350P 4X6 | E5: 4 | I5: 46075 | K5: =+P5 -> -137.75 | L5: =IF(I5="","",SUMIF(제품등록!B:B,'창고1(실사표)'!C:C,제품등록!F:F)) -> 273 | M5: =IF(I5=0,"",I5-L5) -> 45802 | N5: =IF(L5="","",L5*상미75) -> 68.25 | O5: =IF(M5="","",M5+N5) -> 45870.25 | P5: =IF(O5="","",O5-$I$1) -> -137.75
A6: =ROW()-2 -> 4 | B6: 8541 | C6: =VLOOKUP(B:B,재고차이!A:B,2,0) -> PA8541 | D6: =VLOOKUP(C:C,재고차이!B:C,2,0) -> 파워마운틴소분1.5P 2X6 | E6: =32+5 -> 37 | I6: 46191 | K6: =+P6 -> -90.75 | L6: =IF(I6="","",SUMIF(제품등록!B:B,'창고1(실사표)'!C:C,제품등록!F:F)) -> 365 | M6: =IF(I6=0,"",I6-L6) -> 45826 | N6: =IF(L6="","",L6*상미75) -> 91.25 | O6: =IF(M6="","",M6+N6) -> 45917.25 | P6: =IF(O6="","",O6-$I$1) -> -90.75
A7: =ROW()-2 -> 5 | B7: 6871 | C7: =VLOOKUP(B:B,재고차이!A:B,2,0) -> PA6871 | D7: =VLOOKUP(C:C,재고차이!B:C,2,0) -> S)파워 마운틴블라 600PET 4X6 | E7: =38+14 -> 52 | I7: 46197 | K7: =+P7 -> -84.75 | L7: =IF(I7="","",SUMIF(제품등록!B:B,'창고1(실사표)'!C:C,제품등록!F:F)) -> 365 | M7: =IF(I7=0,"",I7-L7) -> 45832 | N7: =IF(L7="","",L7*상미75) -> 91.25 | O7: =IF(M7="","",M7+N7) -> 45923.25 | P7: =IF(O7="","",O7-$I$1) -> -84.75
A8: =ROW()-2 -> 6 | B8: 6277 | C8: =VLOOKUP(B:B,재고차이!A:B,2,0) -> PA6277 | D8: =VLOOKUP(C:C,재고차이!B:C,2,0) -> 파워 퍼플스톰 600PET 4X6 | E8: =15+17 -> 32 | I8: 46192 | K8: =+P8 -> -89.75 | L8: =IF(I8="","",SUMIF(제품등록!B:B,'창고1(실사표)'!C:C,제품등록!F:F)) -> 365 | M8: =IF(I8=0,"",I8-L8) -> 45827 | N8: =IF(L8="","",L8*상미75) -> 91.25 | O8: =IF(M8="","",M8+N8) -> 45918.25 | P8: =IF(O8="","",O8-$I$1) -> -89.75
A9: =ROW()-2 -> 7 | B9: PA0002 | C9: =VLOOKUP(B:B,재고차이!A:B,2,0) -> PA0002 | D9: =VLOOKUP(C:C,재고차이!B:C,2,0) -> 파워 제로 마운틴블라 600PET 4X6 | E9: 3 | I9: 46179 | K9: =+P9 -> -102.75 | L9: =IF(I9="","",SUMIF(제품등록!B:B,'창고1(실사표)'!C:C,제품등록!F:F)) -> 365 | M9: =IF(I9=0,"",I9-L9) -> 45814 | N9: =IF(L9="","",L9*상미75) -> 91.25 | O9: =IF(M9="","",M9+N9) -> 45905.25 | P9: =IF(O9="","",O9-$I$1) -> -102.75
A10: =ROW()-2 -> 8 | B10: PA0002 | C10: =VLOOKUP(B:B,재고차이!A:B,2,0) -> PA0002 | D10: =VLOOKUP(C:C,재고차이!B:C,2,0) -> 파워 제로 마운틴블라 600PET 4X6 | E10: 28 | I10: 46180 | K10: =+P10 -> -101.75 | L10: =IF(I10="","",SUMIF(제품등록!B:B,'창고1(실사표)'!C:C,제품등록!F:F)) -> 365 | M10: =IF(I10=0,"",I10-L10) -> 45815 | N10: =IF(L10="","",L10*상미75) -> 91.25 | O10: =IF(M10="","",M10+N10) -> 45906.25 | P10: =IF(O10="","",O10-$I$1) -> -101.75
A11: =ROW()-2 -> 9 | B11: 6285 | C11: =VLOOKUP(B:B,재고차이!A:B,2,0) -> PA6285 | D11: =VLOOKUP(C:C,재고차이!B:C,2,0) -> S)파워 스칼렛스톰 600PET 4X6 | E11: 1 | I11: 46183 | K11: =+P11 -> -98.75 | L11: =IF(I11="","",SUMIF(제품등록!B:B,'창고1(실사표)'!C:C,제품등록!F:F)) -> 365 | M11: =IF(I11=0,"",I11-L11) -> 45818 | N11: =IF(L11="","",L11*상미75) -> 91.25 | O11: =IF(M11="","",M11+N11) -> 45909.25 | P11: =IF(O11="","",O11-$I$1) -> -98.75
A12: =ROW()-2 -> 10 | B12: 6285 | C12: =VLOOKUP(B:B,재고차이!A:B,2,0) -> PA6285 | D12: =VLOOKUP(C:C,재고차이!B:C,2,0) -> S)파워 스칼렛스톰 600PET 4X6 | E12: 3 | I12: 46184 | K12: =+P12 -> -97.75 | L12: =IF(I12="","",SUMIF(제품등록!B:B,'창고1(실사표)'!C:C,제품등록!F:F)) -> 365 | M12: =IF(I12=0,"",I12-L12) -> 45819 | N12: =IF(L12="","",L12*상미75) -> 91.25 | O12: =IF(M12="","",M12+N12) -> 45910.25 | P12: =IF(O12="","",O12-$I$1) -> -97.75
A13: =ROW()-2 -> 11 | B13: 6285 | C13: =VLOOKUP(B:B,재고차이!A:B,2,0) -> PA6285 | D13: =VLOOKUP(C:C,재고차이!B:C,2,0) -> S)파워 스칼렛스톰 600PET 4X6 | E13: =12+20 -> 32 | I13: 46190 | K13: =+P13 -> -91.75 | L13: =IF(I13="","",SUMIF(제품등록!B:B,'창고1(실사표)'!C:C,제품등록!F:F)) -> 365 | M13: =IF(I13=0,"",I13-L13) -> 45825 | N13: =IF(L13="","",L13*상미75) -> 91.25 | O13: =IF(M13="","",M13+N13) -> 45916.25 | P13: =IF(O13="","",O13-$I$1) -> -91.75
A14: =ROW()-2 -> 12 | B14: 1007 | C14: =VLOOKUP(B:B,재고차이!A:B,2,0) -> PA1007 | D14: =VLOOKUP(C:C,재고차이!B:C,2,0) -> S)파워 제로 라임향 600PET 4X6 | E14: =23+42+46 -> 111 | I14: 46196 | K14: =+P14 -> -85.75 | L14: =IF(I14="","",SUMIF(제품등록!B:B,'창고1(실사표)'!C:C,제품등록!F:F)) -> 365 | M14: =IF(I14=0,"",I14-L14) -> 45831 | N14: =IF(L14="","",L14*상미75) -> 91.25 | O14: =IF(M14="","",M14+N14) -> 45922.25 | P14: =IF(O14="","",O14-$I$1) -> -85.75
A15: =ROW()-2 -> 13 | B15: 8561 | C15: =VLOOKUP(B:B,재고차이!A:B,2,0) -> TR8561 | D15: =VLOOKUP(C:C,재고차이!B:C,2,0) -> 토레타 500ml (소분) | E15: =6+18 -> 24 | I15: 46163 | K15: =+P15 -> -118.75 | L15: =IF(I15="","",SUMIF(제품등록!B:B,'창고1(실사표)'!C:C,제품등록!F:F)) -> 365 | M15: =IF(I15=0,"",I15-L15) -> 45798 | N15: =IF(L15="","",L15*상미75) -> 91.25 | O15: =IF(M15="","",M15+N15) -> 45889.25 | P15: =IF(O15="","",O15-$I$1) -> -118.75
A16: =ROW()-2 -> 14 | B16: 8561 | C16: =VLOOKUP(B:B,재고차이!A:B,2,0) -> TR8561 | D16: =VLOOKUP(C:C,재고차이!B:C,2,0) -> 토레타 500ml (소분) | E16: 28 | I16: 46164 | K16: =+P16 -> -117.75 | L16: =IF(I16="","",SUMIF(제품등록!B:B,'창고1(실사표)'!C:C,제품등록!F:F)) -> 365 | M16: =IF(I16=0,"",I16-L16) -> 45799 | N16: =IF(L16="","",L16*상미75) -> 91.25 | O16: =IF(M16="","",M16+N16) -> 45890.25 | P16: =IF(O16="","",O16-$I$1) -> -117.75
A17: =ROW()-2 -> 15 | B17: 8590 | C17: =VLOOKUP(B:B,재고차이!A:B,2,0) -> TR8590 | D17: =VLOOKUP(C:C,재고차이!B:C,2,0) -> 토레타 제로500PET 4x6 | E17: =12+18+34 -> 64 | I17: 46211 | K17: =+P17 -> -70.75 | L17: =IF(I17="","",SUMIF(제품등록!B:B,'창고1(실사표)'!C:C,제품등록!F:F)) -> 365 | M17: =IF(I17=0,"",I17-L17) -> 45846 | N17: =IF(L17="","",L17*상미75) -> 91.25 | O17: =IF(M17="","",M17+N17) -> 45937.25 | P17: =IF(O17="","",O17-$I$1) -> -70.75
A18: =ROW()-2 -> 16 | B18: IH0001 | C18: =VLOOKUP(B:B,재고차이!A:B,2,0) -> IH0001 | D18: =VLOOKUP(C:C,재고차이!B:C,2,0) -> S)일로하스 피치 540PET 4X6 | E18: =4+15 -> 19 | I18: 46156 | K18: =+P18 -> -125.75 | L18: =IF(I18="","",SUMIF(제품등록!B:B,'창고1(실사표)'!C:C,제품등록!F:F)) -> 365 | M18: =IF(I18=0,"",I18-L18) -> 45791 | N18: =IF(L18="","",L18*상미75) -> 91.25 | O18: =IF(M18="","",M18+N18) -> 45882.25 | P18: =IF(O18="","",O18-$I$1) -> -125.75
A19: =ROW()-2 -> 17 | B19: 1000 | C19: =VLOOKUP(B:B,재고차이!A:B,2,0) -> MM1000 | D19: =VLOOKUP(C:C,재고차이!B:C,2,0) -> 미닛 허니&유자 280PET 4X6 | E19: 3 | I19: 46150 | K19: =+P19 -> -131.75 | L19: =IF(I19="","",SUMIF(제품등록!B:B,'창고1(실사표)'!C:C,제품등록!F:F)) -> 365 | M19: =IF(I19=0,"",I19-L19) -> 45785 | N19: =IF(L19="","",L19*상미75) -> 91.25 | O19: =IF(M19="","",M19+N19) -> 45876.25 | P19: =IF(O19="","",O19-$I$1) -> -131.75
A20: =ROW()-2 -> 18 | B20: 1001 | C20: =VLOOKUP(B:B,재고차이!A:B,2,0) -> MM1001 | D20: =VLOOKUP(C:C,재고차이!B:C,2,0) -> 미닛 모과&생강 280PET 4X6 | E20: 2 | I20: 46242 | K20: =+P20 -> -108.75 | L20: =IF(I20="","",SUMIF(제품등록!B:B,'창고1(실사표)'!C:C,제품등록!F:F)) -> 457 | M20: =IF(I20=0,"",I20-L20) -> 45785 | N20: =IF(L20="","",L20*상미75) -> 114.25 | O20: =IF(M20="","",M20+N20) -> 45899.25 | P20: =IF(O20="","",O20-$I$1) -> -108.75
A21: =ROW()-2 -> 19 | B21: 1002 | C21: =VLOOKUP(B:B,재고차이!A:B,2,0) -> MM1002 | D21: =VLOOKUP(C:C,재고차이!B:C,2,0) -> 미닛 레몬에이드 350PET 4X6 | E21: 9 | I21: 46089 | K21: =+P21 -> -121.5 | L21: =IF(I21="","",SUMIF(제품등록!B:B,'창고1(실사표)'!C:C,제품등록!F:F)) -> 270 | M21: =IF(I21=0,"",I21-L21) -> 45819 | N21: =IF(L21="","",L21*상미75) -> 67.5 | O21: =IF(M21="","",M21+N21) -> 45886.5 | P21: =IF(O21="","",O21-$I$1) -> -121.5
A22: =ROW()-2 -> 20 | B22: 1002 | C22: =VLOOKUP(B:B,재고차이!A:B,2,0) -> MM1002 | D22: =VLOOKUP(C:C,재고차이!B:C,2,0) -> 미닛 레몬에이드 350PET 4X6 | E22: 3 | I22: 46090 | K22: =+P22 -> -120.5 | L22: =IF(I22="","",SUMIF(제품등록!B:B,'창고1(실사표)'!C:C,제품등록!F:F)) -> 270 | M22: =IF(I22=0,"",I22-L22) -> 45820 | N22: =IF(L22="","",L22*상미75) -> 67.5 | O22: =IF(M22="","",M22+N22) -> 45887.5 | P22: =IF(O22="","",O22-$I$1) -> -120.5
A23: =ROW()-2 -> 21 | B23: 8065 | C23: =VLOOKUP(B:B,재고차이!A:B,2,0) -> GG8065 | D23: =VLOOKUP(C:C,재고차이!B:C,2,0) -> 조지아 크래프트 블랙 470PET 4X6 | E23: =14+10 -> 24 | I23: 46191 | K23: =+P23 -> -90.75 | L23: =IF(I23="","",SUMIF(제품등록!B:B,'창고1(실사표)'!C:C,제품등록!F:F)) -> 365 | M23: =IF(I23=0,"",I23-L23) -> 45826 | N23: =IF(L23="","",L23*상미75) -> 91.25 | O23: =IF(M23="","",M23+N23) -> 45917.25 | P23: =IF(O23="","",O23-$I$1) -> -90.75
A24: =ROW()-2 -> 22 | B24: 8066 | C24: =VLOOKUP(B:B,재고차이!A:B,2,0) -> GG8066 | D24: =VLOOKUP(C:C,재고차이!B:C,2,0) -> 조지아 크래프트 라떼 470PET 4X6 | E24: 24 | I24: 46144 | K24: =+P24 -> -92 | L24: =IF(I24="","",SUMIF(제품등록!B:B,'창고1(실사표)'!C:C,제품등록!F:F)) -> 304 | M24: =IF(I24=0,"",I24-L24) -> 45840 | N24: =IF(L24="","",L24*상미75) -> 76 | O24: =IF(M24="","",M24+N24) -> 45916 | P24: =IF(O24="","",O24-$I$1) -> -92
A25: =ROW()-2 -> 23 | B25: 8058 | C25: =VLOOKUP(B:B,재고차이!A:B,2,0) -> GG8058 | D25: =VLOOKUP(C:C,재고차이!B:C,2,0) -> 조지아 크래프트 스윗블랙 470PET 4X6 | E25: =1+8 -> 9 | I25: 46190 | K25: =+P25 -> -91.75 | L25: =IF(I25="","",SUMIF(제품등록!B:B,'창고1(실사표)'!C:C,제품등록!F:F)) -> 365 | M25: =IF(I25=0,"",I25-L25) -> 45825 | N25: =IF(L25="","",L25*상미75) -> 91.25 | O25: =IF(M25="","",M25+N25) -> 45916.25 | P25: =IF(O25="","",O25-$I$1) -> -91.75
A26: =ROW()-2 -> 24 | B26: 8278 | C26: =VLOOKUP(B:B,재고차이!A:B,2,0) -> GG8278 | D26: =VLOOKUP(C:C,재고차이!B:C,2,0) -> 조지아 크래프트 저칼로리라떼 470PET 4X6 | E26: 14 | I26: 46110 | K26: =+P26 -> -126 | L26: =IF(I26="","",SUMIF(제품등록!B:B,'창고1(실사표)'!C:C,제품등록!F:F)) -> 304 | M26: =IF(I26=0,"",I26-L26) -> 45806 | N26: =IF(L26="","",L26*상미75) -> 76 | O26: =IF(M26="","",M26+N26) -> 45882 | P26: =IF(O26="","",O26-$I$1) -> -126
A27: =ROW()-2 -> 25 | B27: 5651 | C27: =VLOOKUP(B:B,재고차이!A:B,2,0) -> PC5651 | D27: =VLOOKUP(C:C,재고차이!B:C,2,0) -> 강원평창수(올림픽) 500PET X20 | E27: 12 | I27: 46164 | K27: =+P27 -> -117.75 | L27: =IF(I27="","",SUMIF(제품등록!B:B,'창고1(실사표)'!C:C,제품등록!F:F)) -> 365 | M27: =IF(I27=0,"",I27-L27) -> 45799 | N27: =IF(L27="","",L27*상미75) -> 91.25 | O27: =IF(M27="","",M27+N27) -> 45890.25 | P27: =IF(O27="","",O27-$I$1) -> -117.75
